Workbook

Sheet Özet
A1: CEPHEPRO - 15 DÖNEMLİ TAŞERON HAKEDİŞ VE FİNANSAL GENEL ÖZET
A3: Proje / Şantiye: | D3: Taşeron Firma:
A4: İşin Adı: | D4: Sözleşme Tarihi:
A5: Hakediş Dönemleri: | B5: 1. - 15. Hakediş Dönemleri (Revize Fiyat Destekli) | D5: Para Birimi: | E5: Türk Lirası (TL)
A7: 15 DÖNEMLİ HAKEDİŞLER BAZINDA FİNANSAL İCMAL VE TEMİNAT HESABI
A8: Hakediş Dönemi | B8: Ana İmalat Tutarı (TL) | C8: Ek Tutanak / Ekstra (TL) | D8: Kesintiler & Cezalar (TL) | E8: Brüt Toplam (Ana+Ek-Kes) | F8: Teminat Kesintisi (%10) | G8: Net Ödenecek Tutar (TL)
A9: 1. Hakediş Dönemi | B9: =SUM('Hakediş Takip'!L7:L30) | C9: =SUMIF('Tutanak ve Ekler'!B6:B100, A9, 'Tutanak ve Ekler'!G6:G100) | D9: =SUMIF(Kesintiler!B6:B100, A9, Kesintiler!G6:G100) | E9: =B9+C9-D9 | F9: =E9*0.1 | G9: =E9-F9
A10: 2. Hakediş Dönemi | B10: =SUM('Hakediş Takip'!P7:P30) | C10: =SUMIF('Tutanak ve Ekler'!B6:B100, A10, 'Tutanak ve Ekler'!G6:G100) | D10: =SUMIF(Kesintiler!B6:B100, A10, Kesintiler!G6:G100) | E10: =B10+C10-D10 | F10: =E10*0.1 | G10: =E10-F10
A11: 3. Hakediş Dönemi | B11: =SUM('Hakediş Takip'!T7:T30) | C11: =SUMIF('Tutanak ve Ekler'!B6:B100, A11, 'Tutanak ve Ekler'!G6:G100) | D11: =SUMIF(Kesintiler!B6:B100, A11, Kesintiler!G6:G100) | E11: =B11+C11-D11 | F11: =E11*0.1 | G11: =E11-F11
A12: 4. Hakediş Dönemi | B12: =SUM('Hakediş Takip'!X7:X30) | C12: =SUMIF('Tutanak ve Ekler'!B6:B100, A12, 'Tutanak ve Ekler'!G6:G100) | D12: =SUMIF(Kesintiler!B6:B100, A12, Kesintiler!G6:G100) | E12: =B12+C12-D12 | F12: =E12*0.1 | G12: =E12-F12
A13: 5. Hakediş Dönemi | B13: =SUM('Hakediş Takip'!AB7:AB30) | C13: =SUMIF('Tutanak ve Ekler'!B6:B100, A13, 'Tutanak ve Ekler'!G6:G100) | D13: =SUMIF(Kesintiler!B6:B100, A13, Kesintiler!G6:G100) | E13: =B13+C13-D13 | F13: =E13*0.1 | G13: =E13-F13
A14: 6. Hakediş Dönemi | B14: =SUM('Hakediş Takip'!AF7:AF30) | C14: =SUMIF('Tutanak ve Ekler'!B6:B100, A14, 'Tutanak ve Ekler'!G6:G100) | D14: =SUMIF(Kesintiler!B6:B100, A14, Kesintiler!G6:G100) | E14: =B14+C14-D14 | F14: =E14*0.1 | G14: =E14-F14
A15: 7. Hakediş Dönemi | B15: =SUM('Hakediş Takip'!AJ7:AJ30) | C15: =SUMIF('Tutanak ve Ekler'!B6:B100, A15, 'Tutanak ve Ekler'!G6:G100) | D15: =SUMIF(Kesintiler!B6:B100, A15, Kesintiler!G6:G100) | E15: =B15+C15-D15 | F15: =E15*0.1 | G15: =E15-F15
A16: 8. Hakediş Dönemi | B16: =SUM('Hakediş Takip'!AN7:AN30) | C16: =SUMIF('Tutanak ve Ekler'!B6:B100, A16, 'Tutanak ve Ekler'!G6:G100) | D16: =SUMIF(Kesintiler!B6:B100, A16, Kesintiler!G6:G100) | E16: =B16+C16-D16 | F16: =E16*0.1 | G16: =E16-F16
A17: 9. Hakediş Dönemi | B17: =SUM('Hakediş Takip'!AR7:AR30) | C17: =SUMIF('Tutanak ve Ekler'!B6:B100, A17, 'Tutanak ve Ekler'!G6:G100) | D17: =SUMIF(Kesintiler!B6:B100, A17, Kesintiler!G6:G100) | E17: =B17+C17-D17 | F17: =E17*0.1 | G17: =E17-F17
A18: 10. Hakediş Dönemi | B18: =SUM('Hakediş Takip'!AV7:AV30) | C18: =SUMIF('Tutanak ve Ekler'!B6:B100, A18, 'Tutanak ve Ekler'!G6:G100) | D18: =SUMIF(Kesintiler!B6:B100, A18, Kesintiler!G6:G100) | E18: =B18+C18-D18 | F18: =E18*0.1 | G18: =E18-F18
A19: 11. Hakediş Dönemi | B19: =SUM('Hakediş Takip'!AZ7:AZ30) | C19: =SUMIF('Tutanak ve Ekler'!B6:B100, A19, 'Tutanak ve Ekler'!G6:G100) | D19: =SUMIF(Kesintiler!B6:B100, A19, Kesintiler!G6:G100) | E19: =B19+C19-D19 | F19: =E19*0.1 | G19: =E19-F19
A20: 12. Hakediş Dönemi | B20: =SUM('Hakediş Takip'!BD7:BD30) | C20: =SUMIF('Tutanak ve Ekler'!B6:B100, A20, 'Tutanak ve Ekler'!G6:G100) | D20: =SUMIF(Kesintiler!B6:B100, A20, Kesintiler!G6:G100) | E20: =B20+C20-D20 | F20: =E20*0.1 | G20: =E20-F20
A21: 13. Hakediş Dönemi | B21: =SUM('Hakediş Takip'!BH7:BH30) | C21: =SUMIF('Tutanak ve Ekler'!B6:B100, A21, 'Tutanak ve Ekler'!G6:G100) | D21: =SUMIF(Kesintiler!B6:B100, A21, Kesintiler!G6:G100) | E21: =B21+C21-D21 | F21: =E21*0.1 | G21: =E21-F21
A22: 14. Hakediş Dönemi | B22: =SUM('Hakediş Takip'!BL7:BL30) | C22: =SUMIF('Tutanak ve Ekler'!B6:B100, A22, 'Tutanak ve Ekler'!G6:G100) | D22: =SUMIF(Kesintiler!B6:B100, A22, Kesintiler!G6:G100) | E22: =B22+C22-D22 | F22: =E22*0.1 | G22: =E22-F22
A23: 15. Hakediş Dönemi | B23: =SUM('Hakediş Takip'!BP7:BP30) | C23: =SUMIF('Tutanak ve Ekler'!B6:B100, A23, 'Tutanak ve Ekler'!G6:G100) | D23: =SUMIF(Kesintiler!B6:B100, A23, Kesintiler!G6:G100) | E23: =B23+C23-D23 | F23: =E23*0.1 | G23: =E23-F23
A24: TOPLAM KÜMÜLATİF HAKEDİŞ (1 - 15) | B24: =SUM(B9:B23) | C24: =SUM(C9:C23) | D24: =SUM(D9:D23) | E24: =SUM(E9:E23) | F24: =SUM(F9:F23) | G24: =SUM(G9:G23)

Sheet Hakediş Takip
A1: 15 DÖNEMLİ TAŞERON HAKEDİŞ VE METRAJ TAKİP SİSTEMİ
A3: 💡 AÇIKLAMA: İş kalemi yazıldığında Poz No ve dönemlere ait Birim Fiyatlar 'Birim Fiyat Master' sayfasından revizyon kurallarına göre otomatik gelir. A - G sütunları dondurulmuştur.
I5: 1. Hakediş Dönemi | M5: 2. Hakediş Dönemi | Q5: 3. Hakediş Dönemi | U5: 4. Hakediş Dönemi | Y5: 5. Hakediş Dönemi | AC5: 6. Hakediş Dönemi | AG5: 7. Hakediş Dönemi | AK5: 8. Hakediş Dönemi | AO5: 9. Hakediş Dönemi | AS5: 10. Hakediş Dönemi | AW5: 11. Hakediş Dönemi | BA5: 12. Hakediş Dönemi | BE5: 13. Hakediş Dönemi | BI5: 14. Hakediş Dönemi | BM5: 15. Hakediş Dönemi
A6: Blok | B6: Cephe | C6: İş Kalemi | D6: Poz No | E6: Birim | F6: Sözleşme Miktarı | G6: Kalan Miktar | H6: Önceki Küm. | I6: 1.Dönem Miktar | J6: 1.Dönem Küm. | K6: 1.Dönem Birim Fiyat | L6: 1.Dönem Tutar | M6: 2.Dönem Miktar | N6: 2.Dönem Küm. | O6: 2.Dönem Birim Fiyat | P6: 2.Dönem Tutar | Q6: 3.Dönem Miktar | R6: 3.Dönem Küm. | S6: 3.Dönem Birim Fiyat | T6: 3.Dönem Tutar | U6: 4.Dönem Miktar | V6: 4.Dönem Küm. | W6: 4.Dönem Birim Fiyat | X6: 4.Dönem Tutar | Y6: 5.Dönem Miktar | Z6: 5.Dönem Küm. | AA6: 5.Dönem Birim Fiyat | AB6: 5.Dönem Tutar | AC6: 6.Dönem Miktar | AD6: 6.Dönem Küm. | AE6: 6.Dönem Birim Fiyat | AF6: 6.Dönem Tutar | AG6: 7.Dönem Miktar | AH6: 7.Dönem Küm. | AI6: 7.Dönem Birim Fiyat | AJ6: 7.Dönem Tutar | AK6: 8.Dönem Miktar | AL6: 8.Dönem Küm. | AM6: 8.Dönem Birim Fiyat | AN6: 8.Dönem Tutar | AO6: 9.Dönem Miktar | AP6: 9.Dönem Küm. | AQ6: 9.Dönem Birim Fiyat | AR6: 9.Dönem Tutar | AS6: 10.Dönem Miktar | AT6: 10.Dönem Küm. | AU6: 10.Dönem Birim Fiyat | AV6: 10.Dönem Tutar | AW6: 11.Dönem Miktar | AX6: 11.Dönem Küm. | AY6: 11.Dönem Birim Fiyat | AZ6: 11.Dönem Tutar | BA6: 12.Dönem Miktar | BB6: 12.Dönem Küm. | BC6: 12.Dönem Birim Fiyat | BD6: 12.Dönem Tutar | BE6: 13.Dönem Miktar | BF6: 13.Dönem Küm. | BG6: 13.Dönem Birim Fiyat | BH6: 13.Dönem Tutar | BI6: 14.Dönem Miktar | BJ6: 14.Dönem Küm. | BK6: 14.Dönem Birim Fiyat | BL6: 14.Dönem Tutar | BM6: 15.Dönem Miktar | BN6: 15.Dönem Küm. | BO6: 15.Dönem Birim Fiyat | BP6: 15.Dönem Tutar
D7: =IFERROR(VLOOKUP(C7, 'Birim Fiyat Master'!A$6:M$30, 2, FALSE), "") | E7: =IFERROR(VLOOKUP(C7, 'Birim Fiyat Master'!A$6:M$30, 3, FALSE), "") | G7: =F7-BM7 | J7: =H7+I7 | K7: =IFERROR(IF(C7="", "", _xludf.IFS(1>=IFERROR(VLOOKUP(C7, 'Birim Fiyat Master'!A$6:M$30, 13, FALSE), 99), VLOOKUP(C7, 'Birim Fiyat Master'!A$6:M$30, 12, FALSE), 1>=IFERROR(VLOOKUP(C7, 'Birim Fiyat Master'!A$6:M$30, 11, FALSE), 99), VLOOKUP(C7, 'Birim Fiyat Master'!A$6:M$30, 10, FALSE), 1>=IFERROR(VLOOKUP(C7, 'Birim Fiyat Master'!A$6:M$30, 9, FALSE), 99), VLOOKUP(C7, 'Birim Fiyat Master'!A$6:M$30, 8, FALSE), 1>=IFERROR(VLOOKUP(C7, 'Birim Fiyat Master'!A$6:M$30, 7, FALSE), 99), VLOOKUP(C7, 'Birim Fiyat Master'!A$6:M$30, 6, FALSE), TRUE, VLOOKUP(C7, 'Birim Fiyat Master'!A$6:M$30, 4, FALSE))), VLOOKUP(C7, 'Birim Fiyat Master'!A$6:M$30, 4, FALSE)) | L7: =I7*K7 | N7: =J7+M7 | O7: =IFERROR(IF(C7="", "", _xludf.IFS(2>=IFERROR(VLOOKUP(C7, 'Birim Fiyat Master'!A$6:M$30, 13, FALSE), 99), VLOOKUP(C7, 'Birim Fiyat Master'!A$6:M$30, 12, FALSE), 2>=IFERROR(VLOOKUP(C7, 'Birim Fiyat Master'!A$6:M$30, 11, FALSE), 99), VLOOKUP(C7, 'Birim Fiyat Master'!A$6:M$30, 10, FALSE), 2>=IFERROR(VLOOKUP(C7, 'Birim Fiyat Master'!A$6:M$30, 9, FALSE), 99), VLOOKUP(C7, 'Birim Fiyat Master'!A$6:M$30, 8, FALSE), 2>=IFERROR(VLOOKUP(C7, 'Birim Fiyat Master'!A$6:M$30, 7, FALSE), 99), VLOOKUP(C7, 'Birim Fiyat Master'!A$6:M$30, 6, FALSE), TRUE, VLOOKUP(C7, 'Birim Fiyat Master'!A$6:M$30, 4, FALSE))), VLOOKUP(C7, 'Birim Fiyat Master'!A$6:M$30, 4, FALSE)) | P7: =M7*O7 | R7: =N7+Q7 | S7: =IFERROR(IF(C7="", "", _xludf.IFS(3>=IFERROR(VLOOKUP(C7, 'Birim Fiyat Master'!A$6:M$30, 13, FALSE), 99), VLOOKUP(C7, 'Birim Fiyat Master'!A$6:M$30, 12, FALSE), 3>=IFERROR(VLOOKUP(C7, 'Birim Fiyat Master'!A$6:M$30, 11, FALSE), 99), VLOOKUP(C7, 'Birim Fiyat Master'!A$6:M$30, 10, FALSE), 3>=IFERROR(VLOOKUP(C7, 'Birim Fiyat Master'!A$6:M$30, 9, FALSE), 99), VLOOKUP(C7, 'Birim Fiyat Master'!A$6:M$30, 8, FALSE), 3>=IFERROR(VLOOKUP(C7, 'Birim Fiyat Master'!A$6:M$30, 7, FALSE), 99), VLOOKUP(C7, 'Birim Fiyat Master'!A$6:M$30, 6, FALSE), TRUE, VLOOKUP(C7, 'Birim Fiyat Master'!A$6:M$30, 4, FALSE))), VLOOKUP(C7, 'Birim Fiyat Master'!A$6:M$30, 4, FALSE)) | T7: =Q7*S7 | V7: =R7+U7 | W7: =IFERROR(IF(C7="", "", _xludf.IFS(4>=IFERROR(VLOOKUP(C7, 'Birim Fiyat Master'!A$6:M$30, 13, FALSE), 99), VLOOKUP(C7, 'Birim Fiyat Master'!A$6:M$30, 12, FALSE), 4>=IFERROR(VLOOKUP(C7, 'Birim Fiyat Master'!A$6:M$30, 11, FALSE), 99), VLOOKUP(C7, 'Birim Fiyat Master'!A$6:M$30, 10, FALSE), 4>=IFERROR(VLOOKUP(C7, 'Birim Fiyat Master'!A$6:M$30, 9, FALSE), 99), VLOOKUP(C7, 'Birim Fiyat Master'!A$6:M$30, 8, FALSE), 4>=IFERROR(VLOOKUP(C7, 'Birim Fiyat Master'!A$6:M$30, 7, FALSE), 99), VLOOKUP(C7, 'Birim Fiyat Master'!A$6:M$30, 6, FALSE), TRUE, VLOOKUP(C7, 'Birim Fiyat Master'!A$6:M$30, 4, FALSE))), VLOOKUP(C7, 'Birim Fiyat Master'!A$6:M$30, 4, FALSE)) | X7: =U7*W7 | Z7: =V7+Y7 | AA7: =IFERROR(IF(C7="", "", _xludf.IFS(5>=IFERROR(VLOOKUP(C7, 'Birim Fiyat Master'!A$6:M$30, 13, FALSE), 99), VLOOKUP(C7, 'Birim Fiyat Master'!A$6:M$30, 12, FALSE), 5>=IFERROR(VLOOKUP(C7, 'Birim Fiyat Master'!A$6:M$30, 11, FALSE), 99), VLOOKUP(C7, 'Birim Fiyat Master'!A$6:M$30, 10, FALSE), 5>=IFERROR(VLOOKUP(C7, 'Birim Fiyat Master'!A$6:M$30, 9, FALSE), 99), VLOOKUP(C7, 'Birim Fiyat Master'!A$6:M$30, 8, FALSE), 5>=IFERROR(VLOOKUP(C7, 'Birim Fiyat Master'!A$6:M$30, 7, FALSE), 99), VLOOKUP(C7, 'Birim Fiyat Master'!A$6:M$30, 6, FALSE), TRUE, VLOOKUP(C7, 'Birim Fiyat Master'!A$6:M$30, 4, FALSE))), VLOOKUP(C7, 'Birim Fiyat Master'!A$6:M$30, 4, FALSE)) | AB7: =Y7*AA7 | AD7: =Z7+AC7 | AE7: =IFERROR(IF(C7="", "", _xludf.IFS(6>=IFERROR(VLOOKUP(C7, 'Birim Fiyat Master'!A$6:M$30, 13, FALSE), 99), VLOOKUP(C7, 'Birim Fiyat Master'!A$6:M$30, 12, FALSE), 6>=IFERROR(VLOOKUP(C7, 'Birim Fiyat Master'!A$6:M$30, 11, FALSE), 99), VLOOKUP(C7, 'Birim Fiyat Master'!A$6:M$30, 10, FALSE), 6>=IFERROR(VLOOKUP(C7, 'Birim Fiyat Master'!A$6:M$30, 9, FALSE), 99), VLOOKUP(C7, 'Birim Fiyat Master'!A$6:M$30, 8, FALSE), 6>=IFERROR(VLOOKUP(C7, 'Birim Fiyat Master'!A$6:M$30, 7, FALSE), 99), VLOOKUP(C7, 'Birim Fiyat Master'!A$6:M$30, 6, FALSE), TRUE, VLOOKUP(C7, 'Birim Fiyat Master'!A$6:M$30, 4, FALSE))), VLOOKUP(C7, 'Birim Fiyat Master'!A$6:M$30, 4, FALSE)) | AF7: =AC7*AE7 | AH7: =AD7+AG7 | AI7: =IFERROR(IF(C7="", "", _xludf.IFS(7>=IFERROR(VLOOKUP(C7, 'Birim Fiyat Master'!A$6:M$30, 13, FALSE), 99), VLOOKUP(C7, 'Birim Fiyat Master'!A$6:M$30, 12, FALSE), 7>=IFERROR(VLOOKUP(C7, 'Birim Fiyat Master'!A$6:M$30, 11, FALSE), 99), VLOOKUP(C7, 'Birim Fiyat Master'!A$6:M$30, 10, FALSE), 7>=IFERROR(VLOOKUP(C7, 'Birim Fiyat Master'!A$6:M$30, 9, FALSE), 99), VLOOKUP(C7, 'Birim Fiyat Master'!A$6:M$30, 8, FALSE), 7>=IFERROR(VLOOKUP(C7, 'Birim Fiyat Master'!A$6:M$30, 7, FALSE), 99), VLOOKUP(C7, 'Birim Fiyat Master'!A$6:M$30, 6, FALSE), TRUE, VLOOKUP(C7, 'Birim Fiyat Master'!A$6:M$30, 4, FALSE))), VLOOKUP(C7, 'Birim Fiyat Master'!A$6:M$30, 4, FALSE)) | AJ7: =AG7*AI7 | AL7: =AH7+AK7 | AM7: =IFERROR(IF(C7="", "", _xludf.IFS(8>=IFERROR(VLOOKUP(C7, 'Birim Fiyat Master'!A$6:M$30, 13, FALSE), 99), VLOOKUP(C7, 'Birim Fiyat Master'!A$6:M$30, 12, FALSE), 8>=IFERROR(VLOOKUP(C7, 'Birim Fiyat Master'!A$6:M$30, 11, FALSE), 99), VLOOKUP(C7, 'Birim Fiyat Master'!A$6:M$30, 10, FALSE), 8>=IFERROR(VLOOKUP(C7, 'Birim Fiyat Master'!A$6:M$30, 9, FALSE), 99), VLOOKUP(C7, 'Birim Fiyat Master'!A$6:M$30, 8, FALSE), 8>=IFERROR(VLOOKUP(C7, 'Birim Fiyat Master'!A$6:M$30, 7, FALSE), 99), VLOOKUP(C7, 'Birim Fiyat Master'!A$6:M$30, 6, FALSE), TRUE, VLOOKUP(C7, 'Birim Fiyat Master'!A$6:M$30, 4, FALSE))), VLOOKUP(C7, 'Birim Fiyat Master'!A$6:M$30, 4, FALSE)) | AN7: =AK7*AM7 | AP7: =AL7+AO7 | AQ7: =IFERROR(IF(C7="", "", _xludf.IFS(9>=IFERROR(VLOOKUP(C7, 'Birim Fiyat Master'!A$6:M$30, 13, FALSE), 99), VLOOKUP(C7, 'Birim Fiyat Master'!A$6:M$30, 12, FALSE), 9>=IFERROR(VLOOKUP(C7, 'Birim Fiyat Master'!A$6:M$30, 11, FALSE), 99), VLOOKUP(C7, 'Birim Fiyat Master'!A$6:M$30, 10, FALSE), 9>=IFERROR(VLOOKUP(C7, 'Birim Fiyat Master'!A$6:M$30, 9, FALSE), 99), VLOOKUP(C7, 'Birim Fiyat Master'!A$6:M$30, 8, FALSE), 9>=IFERROR(VLOOKUP(C7, 'Birim Fiyat Master'!A$6:M$30, 7, FALSE), 99), VLOOKUP(C7, 'Birim Fiyat Master'!A$6:M$30, 6, FALSE), TRUE, VLOOKUP(C7, 'Birim Fiyat Master'!A$6:M$30, 4, FALSE))), VLOOKUP(C7, 'Birim Fiyat Master'!A$6:M$30, 4, FALSE)) | AR7: =AO7*AQ7 | AT7: =AP7+AS7 | AU7: =IFERROR(IF(C7="", "", _xludf.IFS(10>=IFERROR(VLOOKUP(C7, 'Birim Fiyat Master'!A$6:M$30, 13, FALSE), 99), VLOOKUP(C7, 'Birim Fiyat Master'!A$6:M$30, 12, FALSE), 10>=IFERROR(VLOOKUP(C7, 'Birim Fiyat Master'!A$6:M$30, 11, FALSE), 99), VLOOKUP(C7, 'Birim Fiyat Master'!A$6:M$30, 10, FALSE), 10>=IFERROR(VLOOKUP(C7, 'Birim Fiyat Master'!A$6:M$30, 9, FALSE), 99), VLOOKUP(C7, 'Birim Fiyat Master'!A$6:M$30, 8, FALSE), 10>=IFERROR(VLOOKUP(C7, 'Birim Fiyat Master'!A$6:M$30, 7, FALSE), 99), VLOOKUP(C7, 'Birim Fiyat Master'!A$6:M$30, 6, FALSE), TRUE, VLOOKUP(C7, 'Birim Fiyat Master'!A$6:M$30, 4, FALSE))), VLOOKUP(C7, 'Birim Fiyat Master'!A$6:M$30, 4, FALSE)) | AV7: =AS7*AU7 | AX7: =AT7+AW7 | AY7: =IFERROR(IF(C7="", "", _xludf.IFS(11>=IFERROR(VLOOKUP(C7, 'Birim Fiyat Master'!A$6:M$30, 13, FALSE), 99), VLOOKUP(C7, 'Birim Fiyat Master'!A$6:M$30, 12, FALSE), 11>=IFERROR(VLOOKUP(C7, 'Birim Fiyat Master'!A$6:M$30, 11, FALSE), 99), VLOOKUP(C7, 'Birim Fiyat Master'!A$6:M$30, 10, FALSE), 11>=IFERROR(VLOOKUP(C7, 'Birim Fiyat Master'!A$6:M$30, 9, FALSE), 99), VLOOKUP(C7, 'Birim Fiyat Master'!A$6:M$30, 8, FALSE), 11>=IFERROR(VLOOKUP(C7, 'Birim Fiyat Master'!A$6:M$30, 7, FALSE), 99), VLOOKUP(C7, 'Birim Fiyat Master'!A$6:M$30, 6, FALSE), TRUE, VLOOKUP(C7, 'Birim Fiyat Master'!A$6:M$30, 4, FALSE))), VLOOKUP(C7, 'Birim Fiyat Master'!A$6:M$30, 4, FALSE)) | AZ7: =AW7*AY7 | BB7: =AX7+BA7 | BC7: =IFERROR(IF(C7="", "", _xludf.IFS(12>=IFERROR(VLOOKUP(C7, 'Birim Fiyat Master'!A$6:M$30, 13, FALSE), 99), VLOOKUP(C7, 'Birim Fiyat Master'!A$6:M$30, 12, FALSE), 12>=IFERROR(VLOOKUP(C7, 'Birim Fiyat Master'!A$6:M$30, 11, FALSE), 99), VLOOKUP(C7, 'Birim Fiyat Master'!A$6:M$30, 10, FALSE), 12>=IFERROR(VLOOKUP(C7, 'Birim Fiyat Master'!A$6:M$30, 9, FALSE), 99), VLOOKUP(C7, 'Birim Fiyat Master'!A$6:M$30, 8, FALSE), 12>=IFERROR(VLOOKUP(C7, 'Birim Fiyat Master'!A$6:M$30, 7, FALSE), 99), VLOOKUP(C7, 'Birim Fiyat Master'!A$6:M$30, 6, FALSE), TRUE, VLOOKUP(C7, 'Birim Fiyat Master'!A$6:M$30, 4, FALSE))), VLOOKUP(C7, 'Birim Fiyat Master'!A$6:M$30, 4, FALSE)) | BD7: =BA7*BC7 | BF7: =BB7+BE7 | BG7: =IFERROR(IF(C7="", "", _xludf.IFS(13>=IFERROR(VLOOKUP(C7, 'Birim Fiyat Master'!A$6:M$30, 13, FALSE), 99), VLOOKUP(C7, 'Birim Fiyat Master'!A$6:M$30, 12, FALSE), 13>=IFERROR(VLOOKUP(C7, 'Birim Fiyat Master'!A$6:M$30, 11, FALSE), 99), VLOOKUP(C7, 'Birim Fiyat Master'!A$6:M$30, 10, FALSE), 13>=IFERROR(VLOOKUP(C7, 'Birim Fiyat Master'!A$6:M$30, 9, FALSE), 99), VLOOKUP(C7, 'Birim Fiyat Master'!A$6:M$30, 8, FALSE), 13>=IFERROR(VLOOKUP(C7, 'Birim Fiyat Master'!A$6:M$30, 7, FALSE), 99), VLOOKUP(C7, 'Birim Fiyat Master'!A$6:M$30, 6, FALSE), TRUE, VLOOKUP(C7, 'Birim Fiyat Master'!A$6:M$30, 4, FALSE))), VLOOKUP(C7, 'Birim Fiyat Master'!A$6:M$30, 4, FALSE)) | BH7: =BE7*BG7 | BJ7: =BF7+BI7 | BK7: =IFERROR(IF(C7="", "", _xludf.IFS(14>=IFERROR(VLOOKUP(C7, 'Birim Fiyat Master'!A$6:M$30, 13, FALSE), 99), VLOOKUP(C7, 'Birim Fiyat Master'!A$6:M$30, 12, FALSE), 14>=IFERROR(VLOOKUP(C7, 'Birim Fiyat Master'!A$6:M$30, 11, FALSE), 99), VLOOKUP(C7, 'Birim Fiyat Master'!A$6:M$30, 10, FALSE), 14>=IFERROR(VLOOKUP(C7, 'Birim Fiyat Master'!A$6:M$30, 9, FALSE), 99), VLOOKUP(C7, 'Birim Fiyat Master'!A$6:M$30, 8, FALSE), 14>=IFERROR(VLOOKUP(C7, 'Birim Fiyat Master'!A$6:M$30, 7, FALSE), 99), VLOOKUP(C7, 'Birim Fiyat Master'!A$6:M$30, 6, FALSE), TRUE, VLOOKUP(C7, 'Birim Fiyat Master'!A$6:M$30, 4, FALSE))), VLOOKUP(C7, 'Birim Fiyat Master'!A$6:M$30, 4, FALSE)) | BL7: =BI7*BK7 | BN7: =BJ7+BM7 | BO7: =IFERROR(IF(C7="", "", _xludf.IFS(15>=IFERROR(VLOOKUP(C7, 'Birim Fiyat Master'!A$6:M$30, 13, FALSE), 99), VLOOKUP(C7, 'Birim Fiyat Master'!A$6:M$30, 12, FALSE), 15>=IFERROR(VLOOKUP(C7, 'Birim Fiyat Master'!A$6:M$30, 11, FALSE), 99), VLOOKUP(C7, 'Birim Fiyat Master'!A$6:M$30, 10, FALSE), 15>=IFERROR(VLOOKUP(C7, 'Birim Fiyat Master'!A$6:M$30, 9, FALSE), 99), VLOOKUP(C7, 'Birim Fiyat Master'!A$6:M$30, 8, FALSE), 15>=IFERROR(VLOOKUP(C7, 'Birim Fiyat Master'!A$6:M$30, 7, FALSE), 99), VLOOKUP(C7, 'Birim Fiyat Master'!A$6:M$30, 6, FALSE), TRUE, VLOOKUP(C7, 'Birim Fiyat Master'!A$6:M$30, 4, FALSE))), VLOOKUP(C7, 'Birim Fiyat Master'!A$6:M$30, 4, FALSE)) | BP7: =BM7*BO7
D8: =IFERROR(VLOOKUP(C8, 'Birim Fiyat Master'!A$6:M$30, 2, FALSE), "") | E8: =IFERROR(VLOOKUP(C8, 'Birim Fiyat Master'!A$6:M$30, 3, FALSE), "") | G8: =F8-BM8 | J8: =H8+I8 | K8: =IFERROR(IF(C8="", "", _xludf.IFS(1>=IFERROR(VLOOKUP(C8, 'Birim Fiyat Master'!A$6:M$30, 13, FALSE), 99), VLOOKUP(C8, 'Birim Fiyat Master'!A$6:M$30, 12, FALSE), 1>=IFERROR(VLOOKUP(C8, 'Birim Fiyat Master'!A$6:M$30, 11, FALSE), 99), VLOOKUP(C8, 'Birim Fiyat Master'!A$6:M$30, 10, FALSE), 1>=IFERROR(VLOOKUP(C8, 'Birim Fiyat Master'!A$6:M$30, 9, FALSE), 99), VLOOKUP(C8, 'Birim Fiyat Master'!A$6:M$30, 8, FALSE), 1>=IFERROR(VLOOKUP(C8, 'Birim Fiyat Master'!A$6:M$30, 7, FALSE), 99), VLOOKUP(C8, 'Birim Fiyat Master'!A$6:M$30, 6, FALSE), TRUE, VLOOKUP(C8, 'Birim Fiyat Master'!A$6:M$30, 4, FALSE))), VLOOKUP(C8, 'Birim Fiyat Master'!A$6:M$30, 4, FALSE)) | L8: =I8*K8 | N8: =J8+M8 | O8: =IFERROR(IF(C8="", "", _xludf.IFS(2>=IFERROR(VLOOKUP(C8, 'Birim Fiyat Master'!A$6:M$30, 13, FALSE), 99), VLOOKUP(C8, 'Birim Fiyat Master'!A$6:M$30, 12, FALSE), 2>=IFERROR(VLOOKUP(C8, 'Birim Fiyat Master'!A$6:M$30, 11, FALSE), 99), VLOOKUP(C8, 'Birim Fiyat Master'!A$6:M$30, 10, FALSE), 2>=IFERROR(VLOOKUP(C8, 'Birim Fiyat Master'!A$6:M$30, 9, FALSE), 99), VLOOKUP(C8, 'Birim Fiyat Master'!A$6:M$30, 8, FALSE), 2>=IFERROR(VLOOKUP(C8, 'Birim Fiyat Master'!A$6:M$30, 7, FALSE), 99), VLOOKUP(C8, 'Birim Fiyat Master'!A$6:M$30, 6, FALSE), TRUE, VLOOKUP(C8, 'Birim Fiyat Master'!A$6:M$30, 4, FALSE))), VLOOKUP(C8, 'Birim Fiyat Master'!A$6:M$30, 4, FALSE)) | P8: =M8*O8 | R8: =N8+Q8 | S8: =IFERROR(IF(C8="", "", _xludf.IFS(3>=IFERROR(VLOOKUP(C8, 'Birim Fiyat Master'!A$6:M$30, 13, FALSE), 99), VLOOKUP(C8, 'Birim Fiyat Master'!A$6:M$30, 12, FALSE), 3>=IFERROR(VLOOKUP(C8, 'Birim Fiyat Master'!A$6:M$30, 11, FALSE), 99), VLOOKUP(C8, 'Birim Fiyat Master'!A$6:M$30, 10, FALSE), 3>=IFERROR(VLOOKUP(C8, 'Birim Fiyat Master'!A$6:M$30, 9, FALSE), 99), VLOOKUP(C8, 'Birim Fiyat Master'!A$6:M$30, 8, FALSE), 3>=IFERROR(VLOOKUP(C8, 'Birim Fiyat Master'!A$6:M$30, 7, FALSE), 99), VLOOKUP(C8, 'Birim Fiyat Master'!A$6:M$30, 6, FALSE), TRUE, VLOOKUP(C8, 'Birim Fiyat Master'!A$6:M$30, 4, FALSE))), VLOOKUP(C8, 'Birim Fiyat Master'!A$6:M$30, 4, FALSE)) | T8: =Q8*S8 | V8: =R8+U8 | W8: =IFERROR(IF(C8="", "", _xludf.IFS(4>=IFERROR(VLOOKUP(C8, 'Birim Fiyat Master'!A$6:M$30, 13, FALSE), 99), VLOOKUP(C8, 'Birim Fiyat Master'!A$6:M$30, 12, FALSE), 4>=IFERROR(VLOOKUP(C8, 'Birim Fiyat Master'!A$6:M$30, 11, FALSE), 99), VLOOKUP(C8, 'Birim Fiyat Master'!A$6:M$30, 10, FALSE), 4>=IFERROR(VLOOKUP(C8, 'Birim Fiyat Master'!A$6:M$30, 9, FALSE), 99), VLOOKUP(C8, 'Birim Fiyat Master'!A$6:M$30, 8, FALSE), 4>=IFERROR(VLOOKUP(C8, 'Birim Fiyat Master'!A$6:M$30, 7, FALSE), 99), VLOOKUP(C8, 'Birim Fiyat Master'!A$6:M$30, 6, FALSE), TRUE, VLOOKUP(C8, 'Birim Fiyat Master'!A$6:M$30, 4, FALSE))), VLOOKUP(C8, 'Birim Fiyat Master'!A$6:M$30, 4, FALSE)) | X8: =U8*W8 | Z8: =V8+Y8 | AA8: =IFERROR(IF(C8="", "", _xludf.IFS(5>=IFERROR(VLOOKUP(C8, 'Birim Fiyat Master'!A$6:M$30, 13, FALSE), 99), VLOOKUP(C8, 'Birim Fiyat Master'!A$6:M$30, 12, FALSE), 5>=IFERROR(VLOOKUP(C8, 'Birim Fiyat Master'!A$6:M$30, 11, FALSE), 99), VLOOKUP(C8, 'Birim Fiyat Master'!A$6:M$30, 10, FALSE), 5>=IFERROR(VLOOKUP(C8, 'Birim Fiyat Master'!A$6:M$30, 9, FALSE), 99), VLOOKUP(C8, 'Birim Fiyat Master'!A$6:M$30, 8, FALSE), 5>=IFERROR(VLOOKUP(C8, 'Birim Fiyat Master'!A$6:M$30, 7, FALSE), 99), VLOOKUP(C8, 'Birim Fiyat Master'!A$6:M$30, 6, FALSE), TRUE, VLOOKUP(C8, 'Birim Fiyat Master'!A$6:M$30, 4, FALSE))), VLOOKUP(C8, 'Birim Fiyat Master'!A$6:M$30, 4, FALSE)) | AB8: =Y8*AA8 | AD8: =Z8+AC8 | AE8: =IFERROR(IF(C8="", "", _xludf.IFS(6>=IFERROR(VLOOKUP(C8, 'Birim Fiyat Master'!A$6:M$30, 13, FALSE), 99), VLOOKUP(C8, 'Birim Fiyat Master'!A$6:M$30, 12, FALSE), 6>=IFERROR(VLOOKUP(C8, 'Birim Fiyat Master'!A$6:M$30, 11, FALSE), 99), VLOOKUP(C8, 'Birim Fiyat Master'!A$6:M$30, 10, FALSE), 6>=IFERROR(VLOOKUP(C8, 'Birim Fiyat Master'!A$6:M$30, 9, FALSE), 99), VLOOKUP(C8, 'Birim Fiyat Master'!A$6:M$30, 8, FALSE), 6>=IFERROR(VLOOKUP(C8, 'Birim Fiyat Master'!A$6:M$30, 7, FALSE), 99), VLOOKUP(C8, 'Birim Fiyat Master'!A$6:M$30, 6, FALSE), TRUE, VLOOKUP(C8, 'Birim Fiyat Master'!A$6:M$30, 4, FALSE))), VLOOKUP(C8, 'Birim Fiyat Master'!A$6:M$30, 4, FALSE)) | AF8: =AC8*AE8 | AH8: =AD8+AG8 | AI8: =IFERROR(IF(C8="", "", _xludf.IFS(7>=IFERROR(VLOOKUP(C8, 'Birim Fiyat Master'!A$6:M$30, 13, FALSE), 99), VLOOKUP(C8, 'Birim Fiyat Master'!A$6:M$30, 12, FALSE), 7>=IFERROR(VLOOKUP(C8, 'Birim Fiyat Master'!A$6:M$30, 11, FALSE), 99), VLOOKUP(C8, 'Birim Fiyat Master'!A$6:M$30, 10, FALSE), 7>=IFERROR(VLOOKUP(C8, 'Birim Fiyat Master'!A$6:M$30, 9, FALSE), 99), VLOOKUP(C8, 'Birim Fiyat Master'!A$6:M$30, 8, FALSE), 7>=IFERROR(VLOOKUP(C8, 'Birim Fiyat Master'!A$6:M$30, 7, FALSE), 99), VLOOKUP(C8, 'Birim Fiyat Master'!A$6:M$30, 6, FALSE), TRUE, VLOOKUP(C8, 'Birim Fiyat Master'!A$6:M$30, 4, FALSE))), VLOOKUP(C8, 'Birim Fiyat Master'!A$6:M$30, 4, FALSE)) | AJ8: =AG8*AI8 | AL8: =AH8+AK8 | AM8: =IFERROR(IF(C8="", "", _xludf.IFS(8>=IFERROR(VLOOKUP(C8, 'Birim Fiyat Master'!A$6:M$30, 13, FALSE), 99), VLOOKUP(C8, 'Birim Fiyat Master'!A$6:M$30, 12, FALSE), 8>=IFERROR(VLOOKUP(C8, 'Birim Fiyat Master'!A$6:M$30, 11, FALSE), 99), VLOOKUP(C8, 'Birim Fiyat Master'!A$6:M$30, 10, FALSE), 8>=IFERROR(VLOOKUP(C8, 'Birim Fiyat Master'!A$6:M$30, 9, FALSE), 99), VLOOKUP(C8, 'Birim Fiyat Master'!A$6:M$30, 8, FALSE), 8>=IFERROR(VLOOKUP(C8, 'Birim Fiyat Master'!A$6:M$30, 7, FALSE), 99), VLOOKUP(C8, 'Birim Fiyat Master'!A$6:M$30, 6, FALSE), TRUE, VLOOKUP(C8, 'Birim Fiyat Master'!A$6:M$30, 4, FALSE))), VLOOKUP(C8, 'Birim Fiyat Master'!A$6:M$30, 4, FALSE)) | AN8: =AK8*AM8 | AP8: =AL8+AO8 | AQ8: =IFERROR(IF(C8="", "", _xludf.IFS(9>=IFERROR(VLOOKUP(C8, 'Birim Fiyat Master'!A$6:M$30, 13, FALSE), 99), VLOOKUP(C8, 'Birim Fiyat Master'!A$6:M$30, 12, FALSE), 9>=IFERROR(VLOOKUP(C8, 'Birim Fiyat Master'!A$6:M$30, 11, FALSE), 99), VLOOKUP(C8, 'Birim Fiyat Master'!A$6:M$30, 10, FALSE), 9>=IFERROR(VLOOKUP(C8, 'Birim Fiyat Master'!A$6:M$30, 9, FALSE), 99), VLOOKUP(C8, 'Birim Fiyat Master'!A$6:M$30, 8, FALSE), 9>=IFERROR(VLOOKUP(C8, 'Birim Fiyat Master'!A$6:M$30, 7, FALSE), 99), VLOOKUP(C8, 'Birim Fiyat Master'!A$6:M$30, 6, FALSE), TRUE, VLOOKUP(C8, 'Birim Fiyat Master'!A$6:M$30, 4, FALSE))), VLOOKUP(C8, 'Birim Fiyat Master'!A$6:M$30, 4, FALSE)) | AR8: =AO8*AQ8 | AT8: =AP8+AS8 | AU8: =IFERROR(IF(C8="", "", _xludf.IFS(10>=IFERROR(VLOOKUP(C8, 'Birim Fiyat Master'!A$6:M$30, 13, FALSE), 99), VLOOKUP(C8, 'Birim Fiyat Master'!A$6:M$30, 12, FALSE), 10>=IFERROR(VLOOKUP(C8, 'Birim Fiyat Master'!A$6:M$30, 11, FALSE), 99), VLOOKUP(C8, 'Birim Fiyat Master'!A$6:M$30, 10, FALSE), 10>=IFERROR(VLOOKUP(C8, 'Birim Fiyat Master'!A$6:M$30, 9, FALSE), 99), VLOOKUP(C8, 'Birim Fiyat Master'!A$6:M$30, 8, FALSE), 10>=IFERROR(VLOOKUP(C8, 'Birim Fiyat Master'!A$6:M$30, 7, FALSE), 99), VLOOKUP(C8, 'Birim Fiyat Master'!A$6:M$30, 6, FALSE), TRUE, VLOOKUP(C8, 'Birim Fiyat Master'!A$6:M$30, 4, FALSE))), VLOOKUP(C8, 'Birim Fiyat Master'!A$6:M$30, 4, FALSE)) | AV8: =AS8*AU8 | AX8: =AT8+AW8 | AY8: =IFERROR(IF(C8="", "", _xludf.IFS(11>=IFERROR(VLOOKUP(C8, 'Birim Fiyat Master'!A$6:M$30, 13, FALSE), 99), VLOOKUP(C8, 'Birim Fiyat Master'!A$6:M$30, 12, FALSE), 11>=IFERROR(VLOOKUP(C8, 'Birim Fiyat Master'!A$6:M$30, 11, FALSE), 99), VLOOKUP(C8, 'Birim Fiyat Master'!A$6:M$30, 10, FALSE), 11>=IFERROR(VLOOKUP(C8, 'Birim Fiyat Master'!A$6:M$30, 9, FALSE), 99), VLOOKUP(C8, 'Birim Fiyat Master'!A$6:M$30, 8, FALSE), 11>=IFERROR(VLOOKUP(C8, 'Birim Fiyat Master'!A$6:M$30, 7, FALSE), 99), VLOOKUP(C8, 'Birim Fiyat Master'!A$6:M$30, 6, FALSE), TRUE, VLOOKUP(C8, 'Birim Fiyat Master'!A$6:M$30, 4, FALSE))), VLOOKUP(C8, 'Birim Fiyat Master'!A$6:M$30, 4, FALSE)) | AZ8: =AW8*AY8 | BB8: =AX8+BA8 | BC8: =IFERROR(IF(C8="", "", _xludf.IFS(12>=IFERROR(VLOOKUP(C8, 'Birim Fiyat Master'!A$6:M$30, 13, FALSE), 99), VLOOKUP(C8, 'Birim Fiyat Master'!A$6:M$30, 12, FALSE), 12>=IFERROR(VLOOKUP(C8, 'Birim Fiyat Master'!A$6:M$30, 11, FALSE), 99), VLOOKUP(C8, 'Birim Fiyat Master'!A$6:M$30, 10, FALSE), 12>=IFERROR(VLOOKUP(C8, 'Birim Fiyat Master'!A$6:M$30, 9, FALSE), 99), VLOOKUP(C8, 'Birim Fiyat Master'!A$6:M$30, 8, FALSE), 12>=IFERROR(VLOOKUP(C8, 'Birim Fiyat Master'!A$6:M$30, 7, FALSE), 99), VLOOKUP(C8, 'Birim Fiyat Master'!A$6:M$30, 6, FALSE), TRUE, VLOOKUP(C8, 'Birim Fiyat Master'!A$6:M$30, 4, FALSE))), VLOOKUP(C8, 'Birim Fiyat Master'!A$6:M$30, 4, FALSE)) | BD8: =BA8*BC8 | BF8: =BB8+BE8 | BG8: =IFERROR(IF(C8="", "", _xludf.IFS(13>=IFERROR(VLOOKUP(C8, 'Birim Fiyat Master'!A$6:M$30, 13, FALSE), 99), VLOOKUP(C8, 'Birim Fiyat Master'!A$6:M$30, 12, FALSE), 13>=IFERROR(VLOOKUP(C8, 'Birim Fiyat Master'!A$6:M$30, 11, FALSE), 99), VLOOKUP(C8, 'Birim Fiyat Master'!A$6:M$30, 10, FALSE), 13>=IFERROR(VLOOKUP(C8, 'Birim Fiyat Master'!A$6:M$30, 9, FALSE), 99), VLOOKUP(C8, 'Birim Fiyat Master'!A$6:M$30, 8, FALSE), 13>=IFERROR(VLOOKUP(C8, 'Birim Fiyat Master'!A$6:M$30, 7, FALSE), 99), VLOOKUP(C8, 'Birim Fiyat Master'!A$6:M$30, 6, FALSE), TRUE, VLOOKUP(C8, 'Birim Fiyat Master'!A$6:M$30, 4, FALSE))), VLOOKUP(C8, 'Birim Fiyat Master'!A$6:M$30, 4, FALSE)) | BH8: =BE8*BG8 | BJ8: =BF8+BI8 | BK8: =IFERROR(IF(C8="", "", _xludf.IFS(14>=IFERROR(VLOOKUP(C8, 'Birim Fiyat Master'!A$6:M$30, 13, FALSE), 99), VLOOKUP(C8, 'Birim Fiyat Master'!A$6:M$30, 12, FALSE), 14>=IFERROR(VLOOKUP(C8, 'Birim Fiyat Master'!A$6:M$30, 11, FALSE), 99), VLOOKUP(C8, 'Birim Fiyat Master'!A$6:M$30, 10, FALSE), 14>=IFERROR(VLOOKUP(C8, 'Birim Fiyat Master'!A$6:M$30, 9, FALSE), 99), VLOOKUP(C8, 'Birim Fiyat Master'!A$6:M$30, 8, FALSE), 14>=IFERROR(VLOOKUP(C8, 'Birim Fiyat Master'!A$6:M$30, 7, FALSE), 99), VLOOKUP(C8, 'Birim Fiyat Master'!A$6:M$30, 6, FALSE), TRUE, VLOOKUP(C8, 'Birim Fiyat Master'!A$6:M$30, 4, FALSE))), VLOOKUP(C8, 'Birim Fiyat Master'!A$6:M$30, 4, FALSE)) | BL8: =BI8*BK8 | BN8: =BJ8+BM8 | BO8: =IFERROR(IF(C8="", "", _xludf.IFS(15>=IFERROR(VLOOKUP(C8, 'Birim Fiyat Master'!A$6:M$30, 13, FALSE), 99), VLOOKUP(C8, 'Birim Fiyat Master'!A$6:M$30, 12, FALSE), 15>=IFERROR(VLOOKUP(C8, 'Birim Fiyat Master'!A$6:M$30, 11, FALSE), 99), VLOOKUP(C8, 'Birim Fiyat Master'!A$6:M$30, 10, FALSE), 15>=IFERROR(VLOOKUP(C8, 'Birim Fiyat Master'!A$6:M$30, 9, FALSE), 99), VLOOKUP(C8, 'Birim Fiyat Master'!A$6:M$30, 8, FALSE), 15>=IFERROR(VLOOKUP(C8, 'Birim Fiyat Master'!A$6:M$30, 7, FALSE), 99), VLOOKUP(C8, 'Birim Fiyat Master'!A$6:M$30, 6, FALSE), TRUE, VLOOKUP(C8, 'Birim Fiyat Master'!A$6:M$30, 4, FALSE))), VLOOKUP(C8, 'Birim Fiyat Master'!A$6:M$30, 4, FALSE)) | BP8: =BM8*BO8
D9: =IFERROR(VLOOKUP(C9, 'Birim Fiyat Master'!A$6:M$30, 2, FALSE), "") | E9: =IFERROR(VLOOKUP(C9, 'Birim Fiyat Master'!A$6:M$30, 3, FALSE), "") | G9: =F9-BM9 | J9: =H9+I9 | K9: =IFERROR(IF(C9="", "", _xludf.IFS(1>=IFERROR(VLOOKUP(C9, 'Birim Fiyat Master'!A$6:M$30, 13, FALSE), 99), VLOOKUP(C9, 'Birim Fiyat Master'!A$6:M$30, 12, FALSE), 1>=IFERROR(VLOOKUP(C9, 'Birim Fiyat Master'!A$6:M$30, 11, FALSE), 99), VLOOKUP(C9, 'Birim Fiyat Master'!A$6:M$30, 10, FALSE), 1>=IFERROR(VLOOKUP(C9, 'Birim Fiyat Master'!A$6:M$30, 9, FALSE), 99), VLOOKUP(C9, 'Birim Fiyat Master'!A$6:M$30, 8, FALSE), 1>=IFERROR(VLOOKUP(C9, 'Birim Fiyat Master'!A$6:M$30, 7, FALSE), 99), VLOOKUP(C9, 'Birim Fiyat Master'!A$6:M$30, 6, FALSE), TRUE, VLOOKUP(C9, 'Birim Fiyat Master'!A$6:M$30, 4, FALSE))), VLOOKUP(C9, 'Birim Fiyat Master'!A$6:M$30, 4, FALSE)) | L9: =I9*K9 | N9: =J9+M9 | O9: =IFERROR(IF(C9="", "", _xludf.IFS(2>=IFERROR(VLOOKUP(C9, 'Birim Fiyat Master'!A$6:M$30, 13, FALSE), 99), VLOOKUP(C9, 'Birim Fiyat Master'!A$6:M$30, 12, FALSE), 2>=IFERROR(VLOOKUP(C9, 'Birim Fiyat Master'!A$6:M$30, 11, FALSE), 99), VLOOKUP(C9, 'Birim Fiyat Master'!A$6:M$30, 10, FALSE), 2>=IFERROR(VLOOKUP(C9, 'Birim Fiyat Master'!A$6:M$30, 9, FALSE), 99), VLOOKUP(C9, 'Birim Fiyat Master'!A$6:M$30, 8, FALSE), 2>=IFERROR(VLOOKUP(C9, 'Birim Fiyat Master'!A$6:M$30, 7, FALSE), 99), VLOOKUP(C9, 'Birim Fiyat Master'!A$6:M$30, 6, FALSE), TRUE, VLOOKUP(C9, 'Birim Fiyat Master'!A$6:M$30, 4, FALSE))), VLOOKUP(C9, 'Birim Fiyat Master'!A$6:M$30, 4, FALSE)) | P9: =M9*O9 | R9: =N9+Q9 | S9: =IFERROR(IF(C9="", "", _xludf.IFS(3>=IFERROR(VLOOKUP(C9, 'Birim Fiyat Master'!A$6:M$30, 13, FALSE), 99), VLOOKUP(C9, 'Birim Fiyat Master'!A$6:M$30, 12, FALSE), 3>=IFERROR(VLOOKUP(C9, 'Birim Fiyat Master'!A$6:M$30, 11, FALSE), 99), VLOOKUP(C9, 'Birim Fiyat Master'!A$6:M$30, 10, FALSE), 3>=IFERROR(VLOOKUP(C9, 'Birim Fiyat Master'!A$6:M$30, 9, FALSE), 99), VLOOKUP(C9, 'Birim Fiyat Master'!A$6:M$30, 8, FALSE), 3>=IFERROR(VLOOKUP(C9, 'Birim Fiyat Master'!A$6:M$30, 7, FALSE), 99), VLOOKUP(C9, 'Birim Fiyat Master'!A$6:M$30, 6, FALSE), TRUE, VLOOKUP(C9, 'Birim Fiyat Master'!A$6:M$30, 4, FALSE))), VLOOKUP(C9, 'Birim Fiyat Master'!A$6:M$30, 4, FALSE)) | T9: =Q9*S9 | V9: =R9+U9 | W9: =IFERROR(IF(C9="", "", _xludf.IFS(4>=IFERROR(VLOOKUP(C9, 'Birim Fiyat Master'!A$6:M$30, 13, FALSE), 99), VLOOKUP(C9, 'Birim Fiyat Master'!A$6:M$30, 12, FALSE), 4>=IFERROR(VLOOKUP(C9, 'Birim Fiyat Master'!A$6:M$30, 11, FALSE), 99), VLOOKUP(C9, 'Birim Fiyat Master'!A$6:M$30, 10, FALSE), 4>=IFERROR(VLOOKUP(C9, 'Birim Fiyat Master'!A$6:M$30, 9, FALSE), 99), VLOOKUP(C9, 'Birim Fiyat Master'!A$6:M$30, 8, FALSE), 4>=IFERROR(VLOOKUP(C9, 'Birim Fiyat Master'!A$6:M$30, 7, FALSE), 99), VLOOKUP(C9, 'Birim Fiyat Master'!A$6:M$30, 6, FALSE), TRUE, VLOOKUP(C9, 'Birim Fiyat Master'!A$6:M$30, 4, FALSE))), VLOOKUP(C9, 'Birim Fiyat Master'!A$6:M$30, 4, FALSE)) | X9: =U9*W9 | Z9: =V9+Y9 | AA9: =IFERROR(IF(C9="", "", _xludf.IFS(5>=IFERROR(VLOOKUP(C9, 'Birim Fiyat Master'!A$6:M$30, 13, FALSE), 99), VLOOKUP(C9, 'Birim Fiyat Master'!A$6:M$30, 12, FALSE), 5>=IFERROR(VLOOKUP(C9, 'Birim Fiyat Master'!A$6:M$30, 11, FALSE), 99), VLOOKUP(C9, 'Birim Fiyat Master'!A$6:M$30, 10, FALSE), 5>=IFERROR(VLOOKUP(C9, 'Birim Fiyat Master'!A$6:M$30, 9, FALSE), 99), VLOOKUP(C9, 'Birim Fiyat Master'!A$6:M$30, 8, FALSE), 5>=IFERROR(VLOOKUP(C9, 'Birim Fiyat Master'!A$6:M$30, 7, FALSE), 99), VLOOKUP(C9, 'Birim Fiyat Master'!A$6:M$30, 6, FALSE), TRUE, VLOOKUP(C9, 'Birim Fiyat Master'!A$6:M$30, 4, FALSE))), VLOOKUP(C9, 'Birim Fiyat Master'!A$6:M$30, 4, FALSE)) | AB9: =Y9*AA9 | AD9: =Z9+AC9 | AE9: =IFERROR(IF(C9="", "", _xludf.IFS(6>=IFERROR(VLOOKUP(C9, 'Birim Fiyat Master'!A$6:M$30, 13, FALSE), 99), VLOOKUP(C9, 'Birim Fiyat Master'!A$6:M$30, 12, FALSE), 6>=IFERROR(VLOOKUP(C9, 'Birim Fiyat Master'!A$6:M$30, 11, FALSE), 99), VLOOKUP(C9, 'Birim Fiyat Master'!A$6:M$30, 10, FALSE), 6>=IFERROR(VLOOKUP(C9, 'Birim Fiyat Master'!A$6:M$30, 9, FALSE), 99), VLOOKUP(C9, 'Birim Fiyat Master'!A$6:M$30, 8, FALSE), 6>=IFERROR(VLOOKUP(C9, 'Birim Fiyat Master'!A$6:M$30, 7, FALSE), 99), VLOOKUP(C9, 'Birim Fiyat Master'!A$6:M$30, 6, FALSE), TRUE, VLOOKUP(C9, 'Birim Fiyat Master'!A$6:M$30, 4, FALSE))), VLOOKUP(C9, 'Birim Fiyat Master'!A$6:M$30, 4, FALSE)) | AF9: =AC9*AE9 | AH9: =AD9+AG9 | AI9: =IFERROR(IF(C9="", "", _xludf.IFS(7>=IFERROR(VLOOKUP(C9, 'Birim Fiyat Master'!A$6:M$30, 13, FALSE), 99), VLOOKUP(C9, 'Birim Fiyat Master'!A$6:M$30, 12, FALSE), 7>=IFERROR(VLOOKUP(C9, 'Birim Fiyat Master'!A$6:M$30, 11, FALSE), 99), VLOOKUP(C9, 'Birim Fiyat Master'!A$6:M$30, 10, FALSE), 7>=IFERROR(VLOOKUP(C9, 'Birim Fiyat Master'!A$6:M$30, 9, FALSE), 99), VLOOKUP(C9, 'Birim Fiyat Master'!A$6:M$30, 8, FALSE), 7>=IFERROR(VLOOKUP(C9, 'Birim Fiyat Master'!A$6:M$30, 7, FALSE), 99), VLOOKUP(C9, 'Birim Fiyat Master'!A$6:M$30, 6, FALSE), TRUE, VLOOKUP(C9, 'Birim Fiyat Master'!A$6:M$30, 4, FALSE))), VLOOKUP(C9, 'Birim Fiyat Master'!A$6:M$30, 4, FALSE)) | AJ9: =AG9*AI9 | AL9: =AH9+AK9 | AM9: =IFERROR(IF(C9="", "", _xludf.IFS(8>=IFERROR(VLOOKUP(C9, 'Birim Fiyat Master'!A$6:M$30, 13, FALSE), 99), VLOOKUP(C9, 'Birim Fiyat Master'!A$6:M$30, 12, FALSE), 8>=IFERROR(VLOOKUP(C9, 'Birim Fiyat Master'!A$6:M$30, 11, FALSE), 99), VLOOKUP(C9, 'Birim Fiyat Master'!A$6:M$30, 10, FALSE), 8>=IFERROR(VLOOKUP(C9, 'Birim Fiyat Master'!A$6:M$30, 9, FALSE), 99), VLOOKUP(C9, 'Birim Fiyat Master'!A$6:M$30, 8, FALSE), 8>=IFERROR(VLOOKUP(C9, 'Birim Fiyat Master'!A$6:M$30, 7, FALSE), 99), VLOOKUP(C9, 'Birim Fiyat Master'!A$6:M$30, 6, FALSE), TRUE, VLOOKUP(C9, 'Birim Fiyat Master'!A$6:M$30, 4, FALSE))), VLOOKUP(C9, 'Birim Fiyat Master'!A$6:M$30, 4, FALSE)) | AN9: =AK9*AM9 | AP9: =AL9+AO9 | AQ9: =IFERROR(IF(C9="", "", _xludf.IFS(9>=IFERROR(VLOOKUP(C9, 'Birim Fiyat Master'!A$6:M$30, 13, FALSE), 99), VLOOKUP(C9, 'Birim Fiyat Master'!A$6:M$30, 12, FALSE), 9>=IFERROR(VLOOKUP(C9, 'Birim Fiyat Master'!A$6:M$30, 11, FALSE), 99), VLOOKUP(C9, 'Birim Fiyat Master'!A$6:M$30, 10, FALSE), 9>=IFERROR(VLOOKUP(C9, 'Birim Fiyat Master'!A$6:M$30, 9, FALSE), 99), VLOOKUP(C9, 'Birim Fiyat Master'!A$6:M$30, 8, FALSE), 9>=IFERROR(VLOOKUP(C9, 'Birim Fiyat Master'!A$6:M$30, 7, FALSE), 99), VLOOKUP(C9, 'Birim Fiyat Master'!A$6:M$30, 6, FALSE), TRUE, VLOOKUP(C9, 'Birim Fiyat Master'!A$6:M$30, 4, FALSE))), VLOOKUP(C9, 'Birim Fiyat Master'!A$6:M$30, 4, FALSE)) | AR9: =AO9*AQ9 | AT9: =AP9+AS9 | AU9: =IFERROR(IF(C9="", "", _xludf.IFS(10>=IFERROR(VLOOKUP(C9, 'Birim Fiyat Master'!A$6:M$30, 13, FALSE), 99), VLOOKUP(C9, 'Birim Fiyat Master'!A$6:M$30, 12, FALSE), 10>=IFERROR(VLOOKUP(C9, 'Birim Fiyat Master'!A$6:M$30, 11, FALSE), 99), VLOOKUP(C9, 'Birim Fiyat Master'!A$6:M$30, 10, FALSE), 10>=IFERROR(VLOOKUP(C9, 'Birim Fiyat Master'!A$6:M$30, 9, FALSE), 99), VLOOKUP(C9, 'Birim Fiyat Master'!A$6:M$30, 8, FALSE), 10>=IFERROR(VLOOKUP(C9, 'Birim Fiyat Master'!A$6:M$30, 7, FALSE), 99), VLOOKUP(C9, 'Birim Fiyat Master'!A$6:M$30, 6, FALSE), TRUE, VLOOKUP(C9, 'Birim Fiyat Master'!A$6:M$30, 4, FALSE))), VLOOKUP(C9, 'Birim Fiyat Master'!A$6:M$30, 4, FALSE)) | AV9: =AS9*AU9 | AX9: =AT9+AW9 | AY9: =IFERROR(IF(C9="", "", _xludf.IFS(11>=IFERROR(VLOOKUP(C9, 'Birim Fiyat Master'!A$6:M$30, 13, FALSE), 99), VLOOKUP(C9, 'Birim Fiyat Master'!A$6:M$30, 12, FALSE), 11>=IFERROR(VLOOKUP(C9, 'Birim Fiyat Master'!A$6:M$30, 11, FALSE), 99), VLOOKUP(C9, 'Birim Fiyat Master'!A$6:M$30, 10, FALSE), 11>=IFERROR(VLOOKUP(C9, 'Birim Fiyat Master'!A$6:M$30, 9, FALSE), 99), VLOOKUP(C9, 'Birim Fiyat Master'!A$6:M$30, 8, FALSE), 11>=IFERROR(VLOOKUP(C9, 'Birim Fiyat Master'!A$6:M$30, 7, FALSE), 99), VLOOKUP(C9, 'Birim Fiyat Master'!A$6:M$30, 6, FALSE), TRUE, VLOOKUP(C9, 'Birim Fiyat Master'!A$6:M$30, 4, FALSE))), VLOOKUP(C9, 'Birim Fiyat Master'!A$6:M$30, 4, FALSE)) | AZ9: =AW9*AY9 | BB9: =AX9+BA9 | BC9: =IFERROR(IF(C9="", "", _xludf.IFS(12>=IFERROR(VLOOKUP(C9, 'Birim Fiyat Master'!A$6:M$30, 13, FALSE), 99), VLOOKUP(C9, 'Birim Fiyat Master'!A$6:M$30, 12, FALSE), 12>=IFERROR(VLOOKUP(C9, 'Birim Fiyat Master'!A$6:M$30, 11, FALSE), 99), VLOOKUP(C9, 'Birim Fiyat Master'!A$6:M$30, 10, FALSE), 12>=IFERROR(VLOOKUP(C9, 'Birim Fiyat Master'!A$6:M$30, 9, FALSE), 99), VLOOKUP(C9, 'Birim Fiyat Master'!A$6:M$30, 8, FALSE), 12>=IFERROR(VLOOKUP(C9, 'Birim Fiyat Master'!A$6:M$30, 7, FALSE), 99), VLOOKUP(C9, 'Birim Fiyat Master'!A$6:M$30, 6, FALSE), TRUE, VLOOKUP(C9, 'Birim Fiyat Master'!A$6:M$30, 4, FALSE))), VLOOKUP(C9, 'Birim Fiyat Master'!A$6:M$30, 4, FALSE)) | BD9: =BA9*BC9 | BF9: =BB9+BE9 | BG9: =IFERROR(IF(C9="", "", _xludf.IFS(13>=IFERROR(VLOOKUP(C9, 'Birim Fiyat Master'!A$6:M$30, 13, FALSE), 99), VLOOKUP(C9, 'Birim Fiyat Master'!A$6:M$30, 12, FALSE), 13>=IFERROR(VLOOKUP(C9, 'Birim Fiyat Master'!A$6:M$30, 11, FALSE), 99), VLOOKUP(C9, 'Birim Fiyat Master'!A$6:M$30, 10, FALSE), 13>=IFERROR(VLOOKUP(C9, 'Birim Fiyat Master'!A$6:M$30, 9, FALSE), 99), VLOOKUP(C9, 'Birim Fiyat Master'!A$6:M$30, 8, FALSE), 13>=IFERROR(VLOOKUP(C9, 'Birim Fiyat Master'!A$6:M$30, 7, FALSE), 99), VLOOKUP(C9, 'Birim Fiyat Master'!A$6:M$30, 6, FALSE), TRUE, VLOOKUP(C9, 'Birim Fiyat Master'!A$6:M$30, 4, FALSE))), VLOOKUP(C9, 'Birim Fiyat Master'!A$6:M$30, 4, FALSE)) | BH9: =BE9*BG9 | BJ9: =BF9+BI9 | BK9: =IFERROR(IF(C9="", "", _xludf.IFS(14>=IFERROR(VLOOKUP(C9, 'Birim Fiyat Master'!A$6:M$30, 13, FALSE), 99), VLOOKUP(C9, 'Birim Fiyat Master'!A$6:M$30, 12, FALSE), 14>=IFERROR(VLOOKUP(C9, 'Birim Fiyat Master'!A$6:M$30, 11, FALSE), 99), VLOOKUP(C9, 'Birim Fiyat Master'!A$6:M$30, 10, FALSE), 14>=IFERROR(VLOOKUP(C9, 'Birim Fiyat Master'!A$6:M$30, 9, FALSE), 99), VLOOKUP(C9, 'Birim Fiyat Master'!A$6:M$30, 8, FALSE), 14>=IFERROR(VLOOKUP(C9, 'Birim Fiyat Master'!A$6:M$30, 7, FALSE), 99), VLOOKUP(C9, 'Birim Fiyat Master'!A$6:M$30, 6, FALSE), TRUE, VLOOKUP(C9, 'Birim Fiyat Master'!A$6:M$30, 4, FALSE))), VLOOKUP(C9, 'Birim Fiyat Master'!A$6:M$30, 4, FALSE)) | BL9: =BI9*BK9 | BN9: =BJ9+BM9 | BO9: =IFERROR(IF(C9="", "", _xludf.IFS(15>=IFERROR(VLOOKUP(C9, 'Birim Fiyat Master'!A$6:M$30, 13, FALSE), 99), VLOOKUP(C9, 'Birim Fiyat Master'!A$6:M$30, 12, FALSE), 15>=IFERROR(VLOOKUP(C9, 'Birim Fiyat Master'!A$6:M$30, 11, FALSE), 99), VLOOKUP(C9, 'Birim Fiyat Master'!A$6:M$30, 10, FALSE), 15>=IFERROR(VLOOKUP(C9, 'Birim Fiyat Master'!A$6:M$30, 9, FALSE), 99), VLOOKUP(C9, 'Birim Fiyat Master'!A$6:M$30, 8, FALSE), 15>=IFERROR(VLOOKUP(C9, 'Birim Fiyat Master'!A$6:M$30, 7, FALSE), 99), VLOOKUP(C9, 'Birim Fiyat Master'!A$6:M$30, 6, FALSE), TRUE, VLOOKUP(C9, 'Birim Fiyat Master'!A$6:M$30, 4, FALSE))), VLOOKUP(C9, 'Birim Fiyat Master'!A$6:M$30, 4, FALSE)) | BP9: =BM9*BO9
D10: =IFERROR(VLOOKUP(C10, 'Birim Fiyat Master'!A$6:M$30, 2, FALSE), "") | E10: =IFERROR(VLOOKUP(C10, 'Birim Fiyat Master'!A$6:M$30, 3, FALSE), "") | G10: =F10-BM10 | J10: =H10+I10 | K10: =IFERROR(IF(C10="", "", _xludf.IFS(1>=IFERROR(VLOOKUP(C10, 'Birim Fiyat Master'!A$6:M$30, 13, FALSE), 99), VLOOKUP(C10, 'Birim Fiyat Master'!A$6:M$30, 12, FALSE), 1>=IFERROR(VLOOKUP(C10, 'Birim Fiyat Master'!A$6:M$30, 11, FALSE), 99), VLOOKUP(C10, 'Birim Fiyat Master'!A$6:M$30, 10, FALSE), 1>=IFERROR(VLOOKUP(C10, 'Birim Fiyat Master'!A$6:M$30, 9, FALSE), 99), VLOOKUP(C10, 'Birim Fiyat Master'!A$6:M$30, 8, FALSE), 1>=IFERROR(VLOOKUP(C10, 'Birim Fiyat Master'!A$6:M$30, 7, FALSE), 99), VLOOKUP(C10, 'Birim Fiyat Master'!A$6:M$30, 6, FALSE), TRUE, VLOOKUP(C10, 'Birim Fiyat Master'!A$6:M$30, 4, FALSE))), VLOOKUP(C10, 'Birim Fiyat Master'!A$6:M$30, 4, FALSE)) | L10: =I10*K10 | N10: =J10+M10 | O10: =IFERROR(IF(C10="", "", _xludf.IFS(2>=IFERROR(VLOOKUP(C10, 'Birim Fiyat Master'!A$6:M$30, 13, FALSE), 99), VLOOKUP(C10, 'Birim Fiyat Master'!A$6:M$30, 12, FALSE), 2>=IFERROR(VLOOKUP(C10, 'Birim Fiyat Master'!A$6:M$30, 11, FALSE), 99), VLOOKUP(C10, 'Birim Fiyat Master'!A$6:M$30, 10, FALSE), 2>=IFERROR(VLOOKUP(C10, 'Birim Fiyat Master'!A$6:M$30, 9, FALSE), 99), VLOOKUP(C10, 'Birim Fiyat Master'!A$6:M$30, 8, FALSE), 2>=IFERROR(VLOOKUP(C10, 'Birim Fiyat Master'!A$6:M$30, 7, FALSE), 99), VLOOKUP(C10, 'Birim Fiyat Master'!A$6:M$30, 6, FALSE), TRUE, VLOOKUP(C10, 'Birim Fiyat Master'!A$6:M$30, 4, FALSE))), VLOOKUP(C10, 'Birim Fiyat Master'!A$6:M$30, 4, FALSE)) | P10: =M10*O10 | R10: =N10+Q10 | S10: =IFERROR(IF(C10="", "", _xludf.IFS(3>=IFERROR(VLOOKUP(C10, 'Birim Fiyat Master'!A$6:M$30, 13, FALSE), 99), VLOOKUP(C10, 'Birim Fiyat Master'!A$6:M$30, 12, FALSE), 3>=IFERROR(VLOOKUP(C10, 'Birim Fiyat Master'!A$6:M$30, 11, FALSE), 99), VLOOKUP(C10, 'Birim Fiyat Master'!A$6:M$30, 10, FALSE), 3>=IFERROR(VLOOKUP(C10, 'Birim Fiyat Master'!A$6:M$30, 9, FALSE), 99), VLOOKUP(C10, 'Birim Fiyat Master'!A$6:M$30, 8, FALSE), 3>=IFERROR(VLOOKUP(C10, 'Birim Fiyat Master'!A$6:M$30, 7, FALSE), 99), VLOOKUP(C10, 'Birim Fiyat Master'!A$6:M$30, 6, FALSE), TRUE, VLOOKUP(C10, 'Birim Fiyat Master'!A$6:M$30, 4, FALSE))), VLOOKUP(C10, 'Birim Fiyat Master'!A$6:M$30, 4, FALSE)) | T10: =Q10*S10 | V10: =R10+U10 | W10: =IFERROR(IF(C10="", "", _xludf.IFS(4>=IFERROR(VLOOKUP(C10, 'Birim Fiyat Master'!A$6:M$30, 13, FALSE), 99), VLOOKUP(C10, 'Birim Fiyat Master'!A$6:M$30, 12, FALSE), 4>=IFERROR(VLOOKUP(C10, 'Birim Fiyat Master'!A$6:M$30, 11, FALSE), 99), VLOOKUP(C10, 'Birim Fiyat Master'!A$6:M$30, 10, FALSE), 4>=IFERROR(VLOOKUP(C10, 'Birim Fiyat Master'!A$6:M$30, 9, FALSE), 99), VLOOKUP(C10, 'Birim Fiyat Master'!A$6:M$30, 8, FALSE), 4>=IFERROR(VLOOKUP(C10, 'Birim Fiyat Master'!A$6:M$30, 7, FALSE), 99), VLOOKUP(C10, 'Birim Fiyat Master'!A$6:M$30, 6, FALSE), TRUE, VLOOKUP(C10, 'Birim Fiyat Master'!A$6:M$30, 4, FALSE))), VLOOKUP(C10, 'Birim Fiyat Master'!A$6:M$30, 4, FALSE)) | X10: =U10*W10 | Z10: =V10+Y10 | AA10: =IFERROR(IF(C10="", "", _xludf.IFS(5>=IFERROR(VLOOKUP(C10, 'Birim Fiyat Master'!A$6:M$30, 13, FALSE), 99), VLOOKUP(C10, 'Birim Fiyat Master'!A$6:M$30, 12, FALSE), 5>=IFERROR(VLOOKUP(C10, 'Birim Fiyat Master'!A$6:M$30, 11, FALSE), 99), VLOOKUP(C10, 'Birim Fiyat Master'!A$6:M$30, 10, FALSE), 5>=IFERROR(VLOOKUP(C10, 'Birim Fiyat Master'!A$6:M$30, 9, FALSE), 99), VLOOKUP(C10, 'Birim Fiyat Master'!A$6:M$30, 8, FALSE), 5>=IFERROR(VLOOKUP(C10, 'Birim Fiyat Master'!A$6:M$30, 7, FALSE), 99), VLOOKUP(C10, 'Birim Fiyat Master'!A$6:M$30, 6, FALSE), TRUE, VLOOKUP(C10, 'Birim Fiyat Master'!A$6:M$30, 4, FALSE))), VLOOKUP(C10, 'Birim Fiyat Master'!A$6:M$30, 4, FALSE)) | AB10: =Y10*AA10 | AD10: =Z10+AC10 | AE10: =IFERROR(IF(C10="", "", _xludf.IFS(6>=IFERROR(VLOOKUP(C10, 'Birim Fiyat Master'!A$6:M$30, 13, FALSE), 99), VLOOKUP(C10, 'Birim Fiyat Master'!A$6:M$30, 12, FALSE), 6>=IFERROR(VLOOKUP(C10, 'Birim Fiyat Master'!A$6:M$30, 11, FALSE), 99), VLOOKUP(C10, 'Birim Fiyat Master'!A$6:M$30, 10, FALSE), 6>=IFERROR(VLOOKUP(C10, 'Birim Fiyat Master'!A$6:M$30, 9, FALSE), 99), VLOOKUP(C10, 'Birim Fiyat Master'!A$6:M$30, 8, FALSE), 6>=IFERROR(VLOOKUP(C10, 'Birim Fiyat Master'!A$6:M$30, 7, FALSE), 99), VLOOKUP(C10, 'Birim Fiyat Master'!A$6:M$30, 6, FALSE), TRUE, VLOOKUP(C10, 'Birim Fiyat Master'!A$6:M$30, 4, FALSE))), VLOOKUP(C10, 'Birim Fiyat Master'!A$6:M$30, 4, FALSE)) | AF10: =AC10*AE10 | AH10: =AD10+AG10 | AI10: =IFERROR(IF(C10="", "", _xludf.IFS(7>=IFERROR(VLOOKUP(C10, 'Birim Fiyat Master'!A$6:M$30, 13, FALSE), 99), VLOOKUP(C10, 'Birim Fiyat Master'!A$6:M$30, 12, FALSE), 7>=IFERROR(VLOOKUP(C10, 'Birim Fiyat Master'!A$6:M$30, 11, FALSE), 99), VLOOKUP(C10, 'Birim Fiyat Master'!A$6:M$30, 10, FALSE), 7>=IFERROR(VLOOKUP(C10, 'Birim Fiyat Master'!A$6:M$30, 9, FALSE), 99), VLOOKUP(C10, 'Birim Fiyat Master'!A$6:M$30, 8, FALSE), 7>=IFERROR(VLOOKUP(C10, 'Birim Fiyat Master'!A$6:M$30, 7, FALSE), 99), VLOOKUP(C10, 'Birim Fiyat Master'!A$6:M$30, 6, FALSE), TRUE, VLOOKUP(C10, 'Birim Fiyat Master'!A$6:M$30, 4, FALSE))), VLOOKUP(C10, 'Birim Fiyat Master'!A$6:M$30, 4, FALSE)) | AJ10: =AG10*AI10 | AL10: =AH10+AK10 | AM10: =IFERROR(IF(C10="", "", _xludf.IFS(8>=IFERROR(VLOOKUP(C10, 'Birim Fiyat Master'!A$6:M$30, 13, FALSE), 99), VLOOKUP(C10, 'Birim Fiyat Master'!A$6:M$30, 12, FALSE), 8>=IFERROR(VLOOKUP(C10, 'Birim Fiyat Master'!A$6:M$30, 11, FALSE), 99), VLOOKUP(C10, 'Birim Fiyat Master'!A$6:M$30, 10, FALSE), 8>=IFERROR(VLOOKUP(C10, 'Birim Fiyat Master'!A$6:M$30, 9, FALSE), 99), VLOOKUP(C10, 'Birim Fiyat Master'!A$6:M$30, 8, FALSE), 8>=IFERROR(VLOOKUP(C10, 'Birim Fiyat Master'!A$6:M$30, 7, FALSE), 99), VLOOKUP(C10, 'Birim Fiyat Master'!A$6:M$30, 6, FALSE), TRUE, VLOOKUP(C10, 'Birim Fiyat Master'!A$6:M$30, 4, FALSE))), VLOOKUP(C10, 'Birim Fiyat Master'!A$6:M$30, 4, FALSE)) | AN10: =AK10*AM10 | AP10: =AL10+AO10 | AQ10: =IFERROR(IF(C10="", "", _xludf.IFS(9>=IFERROR(VLOOKUP(C10, 'Birim Fiyat Master'!A$6:M$30, 13, FALSE), 99), VLOOKUP(C10, 'Birim Fiyat Master'!A$6:M$30, 12, FALSE), 9>=IFERROR(VLOOKUP(C10, 'Birim Fiyat Master'!A$6:M$30, 11, FALSE), 99), VLOOKUP(C10, 'Birim Fiyat Master'!A$6:M$30, 10, FALSE), 9>=IFERROR(VLOOKUP(C10, 'Birim Fiyat Master'!A$6:M$30, 9, FALSE), 99), VLOOKUP(C10, 'Birim Fiyat Master'!A$6:M$30, 8, FALSE), 9>=IFERROR(VLOOKUP(C10, 'Birim Fiyat Master'!A$6:M$30, 7, FALSE), 99), VLOOKUP(C10, 'Birim Fiyat Master'!A$6:M$30, 6, FALSE), TRUE, VLOOKUP(C10, 'Birim Fiyat Master'!A$6:M$30, 4, FALSE))), VLOOKUP(C10, 'Birim Fiyat Master'!A$6:M$30, 4, FALSE)) | AR10: =AO10*AQ10 | AT10: =AP10+AS10 | AU10: =IFERROR(IF(C10="", "", _xludf.IFS(10>=IFERROR(VLOOKUP(C10, 'Birim Fiyat Master'!A$6:M$30, 13, FALSE), 99), VLOOKUP(C10, 'Birim Fiyat Master'!A$6:M$30, 12, FALSE), 10>=IFERROR(VLOOKUP(C10, 'Birim Fiyat Master'!A$6:M$30, 11, FALSE), 99), VLOOKUP(C10, 'Birim Fiyat Master'!A$6:M$30, 10, FALSE), 10>=IFERROR(VLOOKUP(C10, 'Birim Fiyat Master'!A$6:M$30, 9, FALSE), 99), VLOOKUP(C10, 'Birim Fiyat Master'!A$6:M$30, 8, FALSE), 10>=IFERROR(VLOOKUP(C10, 'Birim Fiyat Master'!A$6:M$30, 7, FALSE), 99), VLOOKUP(C10, 'Birim Fiyat Master'!A$6:M$30, 6, FALSE), TRUE, VLOOKUP(C10, 'Birim Fiyat Master'!A$6:M$30, 4, FALSE))), VLOOKUP(C10, 'Birim Fiyat Master'!A$6:M$30, 4, FALSE)) | AV10: =AS10*AU10 | AX10: =AT10+AW10 | AY10: =IFERROR(IF(C10="", "", _xludf.IFS(11>=IFERROR(VLOOKUP(C10, 'Birim Fiyat Master'!A$6:M$30, 13, FALSE), 99), VLOOKUP(C10, 'Birim Fiyat Master'!A$6:M$30, 12, FALSE), 11>=IFERROR(VLOOKUP(C10, 'Birim Fiyat Master'!A$6:M$30, 11, FALSE), 99), VLOOKUP(C10, 'Birim Fiyat Master'!A$6:M$30, 10, FALSE), 11>=IFERROR(VLOOKUP(C10, 'Birim Fiyat Master'!A$6:M$30, 9, FALSE), 99), VLOOKUP(C10, 'Birim Fiyat Master'!A$6:M$30, 8, FALSE), 11>=IFERROR(VLOOKUP(C10, 'Birim Fiyat Master'!A$6:M$30, 7, FALSE), 99), VLOOKUP(C10, 'Birim Fiyat Master'!A$6:M$30, 6, FALSE), TRUE, VLOOKUP(C10, 'Birim Fiyat Master'!A$6:M$30, 4, FALSE))), VLOOKUP(C10, 'Birim Fiyat Master'!A$6:M$30, 4, FALSE)) | AZ10: =AW10*AY10 | BB10: =AX10+BA10 | BC10: =IFERROR(IF(C10="", "", _xludf.IFS(12>=IFERROR(VLOOKUP(C10, 'Birim Fiyat Master'!A$6:M$30, 13, FALSE), 99), VLOOKUP(C10, 'Birim Fiyat Master'!A$6:M$30, 12, FALSE), 12>=IFERROR(VLOOKUP(C10, 'Birim Fiyat Master'!A$6:M$30, 11, FALSE), 99), VLOOKUP(C10, 'Birim Fiyat Master'!A$6:M$30, 10, FALSE), 12>=IFERROR(VLOOKUP(C10, 'Birim Fiyat Master'!A$6:M$30, 9, FALSE), 99), VLOOKUP(C10, 'Birim Fiyat Master'!A$6:M$30, 8, FALSE), 12>=IFERROR(VLOOKUP(C10, 'Birim Fiyat Master'!A$6:M$30, 7, FALSE), 99), VLOOKUP(C10, 'Birim Fiyat Master'!A$6:M$30, 6, FALSE), TRUE, VLOOKUP(C10, 'Birim Fiyat Master'!A$6:M$30, 4, FALSE))), VLOOKUP(C10, 'Birim Fiyat Master'!A$6:M$30, 4, FALSE)) | BD10: =BA10*BC10 | BF10: =BB10+BE10 | BG10: =IFERROR(IF(C10="", "", _xludf.IFS(13>=IFERROR(VLOOKUP(C10, 'Birim Fiyat Master'!A$6:M$30, 13, FALSE), 99), VLOOKUP(C10, 'Birim Fiyat Master'!A$6:M$30, 12, FALSE), 13>=IFERROR(VLOOKUP(C10, 'Birim Fiyat Master'!A$6:M$30, 11, FALSE), 99), VLOOKUP(C10, 'Birim Fiyat Master'!A$6:M$30, 10, FALSE), 13>=IFERROR(VLOOKUP(C10, 'Birim Fiyat Master'!A$6:M$30, 9, FALSE), 99), VLOOKUP(C10, 'Birim Fiyat Master'!A$6:M$30, 8, FALSE), 13>=IFERROR(VLOOKUP(C10, 'Birim Fiyat Master'!A$6:M$30, 7, FALSE), 99), VLOOKUP(C10, 'Birim Fiyat Master'!A$6:M$30, 6, FALSE), TRUE, VLOOKUP(C10, 'Birim Fiyat Master'!A$6:M$30, 4, FALSE))), VLOOKUP(C10, 'Birim Fiyat Master'!A$6:M$30, 4, FALSE)) | BH10: =BE10*BG10 | BJ10: =BF10+BI10 | BK10: =IFERROR(IF(C10="", "", _xludf.IFS(14>=IFERROR(VLOOKUP(C10, 'Birim Fiyat Master'!A$6:M$30, 13, FALSE), 99), VLOOKUP(C10, 'Birim Fiyat Master'!A$6:M$30, 12, FALSE), 14>=IFERROR(VLOOKUP(C10, 'Birim Fiyat Master'!A$6:M$30, 11, FALSE), 99), VLOOKUP(C10, 'Birim Fiyat Master'!A$6:M$30, 10, FALSE), 14>=IFERROR(VLOOKUP(C10, 'Birim Fiyat Master'!A$6:M$30, 9, FALSE), 99), VLOOKUP(C10, 'Birim Fiyat Master'!A$6:M$30, 8, FALSE), 14>=IFERROR(VLOOKUP(C10, 'Birim Fiyat Master'!A$6:M$30, 7, FALSE), 99), VLOOKUP(C10, 'Birim Fiyat Master'!A$6:M$30, 6, FALSE), TRUE, VLOOKUP(C10, 'Birim Fiyat Master'!A$6:M$30, 4, FALSE))), VLOOKUP(C10, 'Birim Fiyat Master'!A$6:M$30, 4, FALSE)) | BL10: =BI10*BK10 | BN10: =BJ10+BM10 | BO10: =IFERROR(IF(C10="", "", _xludf.IFS(15>=IFERROR(VLOOKUP(C10, 'Birim Fiyat Master'!A$6:M$30, 13, FALSE), 99), VLOOKUP(C10, 'Birim Fiyat Master'!A$6:M$30, 12, FALSE), 15>=IFERROR(VLOOKUP(C10, 'Birim Fiyat Master'!A$6:M$30, 11, FALSE), 99), VLOOKUP(C10, 'Birim Fiyat Master'!A$6:M$30, 10, FALSE), 15>=IFERROR(VLOOKUP(C10, 'Birim Fiyat Master'!A$6:M$30, 9, FALSE), 99), VLOOKUP(C10, 'Birim Fiyat Master'!A$6:M$30, 8, FALSE), 15>=IFERROR(VLOOKUP(C10, 'Birim Fiyat Master'!A$6:M$30, 7, FALSE), 99), VLOOKUP(C10, 'Birim Fiyat Master'!A$6:M$30, 6, FALSE), TRUE, VLOOKUP(C10, 'Birim Fiyat Master'!A$6:M$30, 4, FALSE))), VLOOKUP(C10, 'Birim Fiyat Master'!A$6:M$30, 4, FALSE)) | BP10: =BM10*BO10
D11: =IFERROR(VLOOKUP(C11, 'Birim Fiyat Master'!A$6:M$30, 2, FALSE), "") | E11: =IFERROR(VLOOKUP(C11, 'Birim Fiyat Master'!A$6:M$30, 3, FALSE), "") | G11: =F11-BM11 | J11: =H11+I11 | K11: =IFERROR(IF(C11="", "", _xludf.IFS(1>=IFERROR(VLOOKUP(C11, 'Birim Fiyat Master'!A$6:M$30, 13, FALSE), 99), VLOOKUP(C11, 'Birim Fiyat Master'!A$6:M$30, 12, FALSE), 1>=IFERROR(VLOOKUP(C11, 'Birim Fiyat Master'!A$6:M$30, 11, FALSE), 99), VLOOKUP(C11, 'Birim Fiyat Master'!A$6:M$30, 10, FALSE), 1>=IFERROR(VLOOKUP(C11, 'Birim Fiyat Master'!A$6:M$30, 9, FALSE), 99), VLOOKUP(C11, 'Birim Fiyat Master'!A$6:M$30, 8, FALSE), 1>=IFERROR(VLOOKUP(C11, 'Birim Fiyat Master'!A$6:M$30, 7, FALSE), 99), VLOOKUP(C11, 'Birim Fiyat Master'!A$6:M$30, 6, FALSE), TRUE, VLOOKUP(C11, 'Birim Fiyat Master'!A$6:M$30, 4, FALSE))), VLOOKUP(C11, 'Birim Fiyat Master'!A$6:M$30, 4, FALSE)) | L11: =I11*K11 | N11: =J11+M11 | O11: =IFERROR(IF(C11="", "", _xludf.IFS(2>=IFERROR(VLOOKUP(C11, 'Birim Fiyat Master'!A$6:M$30, 13, FALSE), 99), VLOOKUP(C11, 'Birim Fiyat Master'!A$6:M$30, 12, FALSE), 2>=IFERROR(VLOOKUP(C11, 'Birim Fiyat Master'!A$6:M$30, 11, FALSE), 99), VLOOKUP(C11, 'Birim Fiyat Master'!A$6:M$30, 10, FALSE), 2>=IFERROR(VLOOKUP(C11, 'Birim Fiyat Master'!A$6:M$30, 9, FALSE), 99), VLOOKUP(C11, 'Birim Fiyat Master'!A$6:M$30, 8, FALSE), 2>=IFERROR(VLOOKUP(C11, 'Birim Fiyat Master'!A$6:M$30, 7, FALSE), 99), VLOOKUP(C11, 'Birim Fiyat Master'!A$6:M$30, 6, FALSE), TRUE, VLOOKUP(C11, 'Birim Fiyat Master'!A$6:M$30, 4, FALSE))), VLOOKUP(C11, 'Birim Fiyat Master'!A$6:M$30, 4, FALSE)) | P11: =M11*O11 | R11: =N11+Q11 | S11: =IFERROR(IF(C11="", "", _xludf.IFS(3>=IFERROR(VLOOKUP(C11, 'Birim Fiyat Master'!A$6:M$30, 13, FALSE), 99), VLOOKUP(C11, 'Birim Fiyat Master'!A$6:M$30, 12, FALSE), 3>=IFERROR(VLOOKUP(C11, 'Birim Fiyat Master'!A$6:M$30, 11, FALSE), 99), VLOOKUP(C11, 'Birim Fiyat Master'!A$6:M$30, 10, FALSE), 3>=IFERROR(VLOOKUP(C11, 'Birim Fiyat Master'!A$6:M$30, 9, FALSE), 99), VLOOKUP(C11, 'Birim Fiyat Master'!A$6:M$30, 8, FALSE), 3>=IFERROR(VLOOKUP(C11, 'Birim Fiyat Master'!A$6:M$30, 7, FALSE), 99), VLOOKUP(C11, 'Birim Fiyat Master'!A$6:M$30, 6, FALSE), TRUE, VLOOKUP(C11, 'Birim Fiyat Master'!A$6:M$30, 4, FALSE))), VLOOKUP(C11, 'Birim Fiyat Master'!A$6:M$30, 4, FALSE)) | T11: =Q11*S11 | V11: =R11+U11 | W11: =IFERROR(IF(C11="", "", _xludf.IFS(4>=IFERROR(VLOOKUP(C11, 'Birim Fiyat Master'!A$6:M$30, 13, FALSE), 99), VLOOKUP(C11, 'Birim Fiyat Master'!A$6:M$30, 12, FALSE), 4>=IFERROR(VLOOKUP(C11, 'Birim Fiyat Master'!A$6:M$30, 11, FALSE), 99), VLOOKUP(C11, 'Birim Fiyat Master'!A$6:M$30, 10, FALSE), 4>=IFERROR(VLOOKUP(C11, 'Birim Fiyat Master'!A$6:M$30, 9, FALSE), 99), VLOOKUP(C11, 'Birim Fiyat Master'!A$6:M$30, 8, FALSE), 4>=IFERROR(VLOOKUP(C11, 'Birim Fiyat Master'!A$6:M$30, 7, FALSE), 99), VLOOKUP(C11, 'Birim Fiyat Master'!A$6:M$30, 6, FALSE), TRUE, VLOOKUP(C11, 'Birim Fiyat Master'!A$6:M$30, 4, FALSE))), VLOOKUP(C11, 'Birim Fiyat Master'!A$6:M$30, 4, FALSE)) | X11: =U11*W11 | Z11: =V11+Y11 | AA11: =IFERROR(IF(C11="", "", _xludf.IFS(5>=IFERROR(VLOOKUP(C11, 'Birim Fiyat Master'!A$6:M$30, 13, FALSE), 99), VLOOKUP(C11, 'Birim Fiyat Master'!A$6:M$30, 12, FALSE), 5>=IFERROR(VLOOKUP(C11, 'Birim Fiyat Master'!A$6:M$30, 11, FALSE), 99), VLOOKUP(C11, 'Birim Fiyat Master'!A$6:M$30, 10, FALSE), 5>=IFERROR(VLOOKUP(C11, 'Birim Fiyat Master'!A$6:M$30, 9, FALSE), 99), VLOOKUP(C11, 'Birim Fiyat Master'!A$6:M$30, 8, FALSE), 5>=IFERROR(VLOOKUP(C11, 'Birim Fiyat Master'!A$6:M$30, 7, FALSE), 99), VLOOKUP(C11, 'Birim Fiyat Master'!A$6:M$30, 6, FALSE), TRUE, VLOOKUP(C11, 'Birim Fiyat Master'!A$6:M$30, 4, FALSE))), VLOOKUP(C11, 'Birim Fiyat Master'!A$6:M$30, 4, FALSE)) | AB11: =Y11*AA11 | AD11: =Z11+AC11 | AE11: =IFERROR(IF(C11="", "", _xludf.IFS(6>=IFERROR(VLOOKUP(C11, 'Birim Fiyat Master'!A$6:M$30, 13, FALSE), 99), VLOOKUP(C11, 'Birim Fiyat Master'!A$6:M$30, 12, FALSE), 6>=IFERROR(VLOOKUP(C11, 'Birim Fiyat Master'!A$6:M$30, 11, FALSE), 99), VLOOKUP(C11, 'Birim Fiyat Master'!A$6:M$30, 10, FALSE), 6>=IFERROR(VLOOKUP(C11, 'Birim Fiyat Master'!A$6:M$30, 9, FALSE), 99), VLOOKUP(C11, 'Birim Fiyat Master'!A$6:M$30, 8, FALSE), 6>=IFERROR(VLOOKUP(C11, 'Birim Fiyat Master'!A$6:M$30, 7, FALSE), 99), VLOOKUP(C11, 'Birim Fiyat Master'!A$6:M$30, 6, FALSE), TRUE, VLOOKUP(C11, 'Birim Fiyat Master'!A$6:M$30, 4, FALSE))), VLOOKUP(C11, 'Birim Fiyat Master'!A$6:M$30, 4, FALSE)) | AF11: =AC11*AE11 | AH11: =AD11+AG11 | AI11: =IFERROR(IF(C11="", "", _xludf.IFS(7>=IFERROR(VLOOKUP(C11, 'Birim Fiyat Master'!A$6:M$30, 13, FALSE), 99), VLOOKUP(C11, 'Birim Fiyat Master'!A$6:M$30, 12, FALSE), 7>=IFERROR(VLOOKUP(C11, 'Birim Fiyat Master'!A$6:M$30, 11, FALSE), 99), VLOOKUP(C11, 'Birim Fiyat Master'!A$6:M$30, 10, FALSE), 7>=IFERROR(VLOOKUP(C11, 'Birim Fiyat Master'!A$6:M$30, 9, FALSE), 99), VLOOKUP(C11, 'Birim Fiyat Master'!A$6:M$30, 8, FALSE), 7>=IFERROR(VLOOKUP(C11, 'Birim Fiyat Master'!A$6:M$30, 7, FALSE), 99), VLOOKUP(C11, 'Birim Fiyat Master'!A$6:M$30, 6, FALSE), TRUE, VLOOKUP(C11, 'Birim Fiyat Master'!A$6:M$30, 4, FALSE))), VLOOKUP(C11, 'Birim Fiyat Master'!A$6:M$30, 4, FALSE)) | AJ11: =AG11*AI11 | AL11: =AH11+AK11 | AM11: =IFERROR(IF(C11="", "", _xludf.IFS(8>=IFERROR(VLOOKUP(C11, 'Birim Fiyat Master'!A$6:M$30, 13, FALSE), 99), VLOOKUP(C11, 'Birim Fiyat Master'!A$6:M$30, 12, FALSE), 8>=IFERROR(VLOOKUP(C11, 'Birim Fiyat Master'!A$6:M$30, 11, FALSE), 99), VLOOKUP(C11, 'Birim Fiyat Master'!A$6:M$30, 10, FALSE), 8>=IFERROR(VLOOKUP(C11, 'Birim Fiyat Master'!A$6:M$30, 9, FALSE), 99), VLOOKUP(C11, 'Birim Fiyat Master'!A$6:M$30, 8, FALSE), 8>=IFERROR(VLOOKUP(C11, 'Birim Fiyat Master'!A$6:M$30, 7, FALSE), 99), VLOOKUP(C11, 'Birim Fiyat Master'!A$6:M$30, 6, FALSE), TRUE, VLOOKUP(C11, 'Birim Fiyat Master'!A$6:M$30, 4, FALSE))), VLOOKUP(C11, 'Birim Fiyat Master'!A$6:M$30, 4, FALSE)) | AN11: =AK11*AM11 | AP11: =AL11+AO11 | AQ11: =IFERROR(IF(C11="", "", _xludf.IFS(9>=IFERROR(VLOOKUP(C11, 'Birim Fiyat Master'!A$6:M$30, 13, FALSE), 99), VLOOKUP(C11, 'Birim Fiyat Master'!A$6:M$30, 12, FALSE), 9>=IFERROR(VLOOKUP(C11, 'Birim Fiyat Master'!A$6:M$30, 11, FALSE), 99), VLOOKUP(C11, 'Birim Fiyat Master'!A$6:M$30, 10, FALSE), 9>=IFERROR(VLOOKUP(C11, 'Birim Fiyat Master'!A$6:M$30, 9, FALSE), 99), VLOOKUP(C11, 'Birim Fiyat Master'!A$6:M$30, 8, FALSE), 9>=IFERROR(VLOOKUP(C11, 'Birim Fiyat Master'!A$6:M$30, 7, FALSE), 99), VLOOKUP(C11, 'Birim Fiyat Master'!A$6:M$30, 6, FALSE), TRUE, VLOOKUP(C11, 'Birim Fiyat Master'!A$6:M$30, 4, FALSE))), VLOOKUP(C11, 'Birim Fiyat Master'!A$6:M$30, 4, FALSE)) | AR11: =AO11*AQ11 | AT11: =AP11+AS11 | AU11: =IFERROR(IF(C11="", "", _xludf.IFS(10>=IFERROR(VLOOKUP(C11, 'Birim Fiyat Master'!A$6:M$30, 13, FALSE), 99), VLOOKUP(C11, 'Birim Fiyat Master'!A$6:M$30, 12, FALSE), 10>=IFERROR(VLOOKUP(C11, 'Birim Fiyat Master'!A$6:M$30, 11, FALSE), 99), VLOOKUP(C11, 'Birim Fiyat Master'!A$6:M$30, 10, FALSE), 10>=IFERROR(VLOOKUP(C11, 'Birim Fiyat Master'!A$6:M$30, 9, FALSE), 99), VLOOKUP(C11, 'Birim Fiyat Master'!A$6:M$30, 8, FALSE), 10>=IFERROR(VLOOKUP(C11, 'Birim Fiyat Master'!A$6:M$30, 7, FALSE), 99), VLOOKUP(C11, 'Birim Fiyat Master'!A$6:M$30, 6, FALSE), TRUE, VLOOKUP(C11, 'Birim Fiyat Master'!A$6:M$30, 4, FALSE))), VLOOKUP(C11, 'Birim Fiyat Master'!A$6:M$30, 4, FALSE)) | AV11: =AS11*AU11 | AX11: =AT11+AW11 | AY11: =IFERROR(IF(C11="", "", _xludf.IFS(11>=IFERROR(VLOOKUP(C11, 'Birim Fiyat Master'!A$6:M$30, 13, FALSE), 99), VLOOKUP(C11, 'Birim Fiyat Master'!A$6:M$30, 12, FALSE), 11>=IFERROR(VLOOKUP(C11, 'Birim Fiyat Master'!A$6:M$30, 11, FALSE), 99), VLOOKUP(C11, 'Birim Fiyat Master'!A$6:M$30, 10, FALSE), 11>=IFERROR(VLOOKUP(C11, 'Birim Fiyat Master'!A$6:M$30, 9, FALSE), 99), VLOOKUP(C11, 'Birim Fiyat Master'!A$6:M$30, 8, FALSE), 11>=IFERROR(VLOOKUP(C11, 'Birim Fiyat Master'!A$6:M$30, 7, FALSE), 99), VLOOKUP(C11, 'Birim Fiyat Master'!A$6:M$30, 6, FALSE), TRUE, VLOOKUP(C11, 'Birim Fiyat Master'!A$6:M$30, 4, FALSE))), VLOOKUP(C11, 'Birim Fiyat Master'!A$6:M$30, 4, FALSE)) | AZ11: =AW11*AY11 | BB11: =AX11+BA11 | BC11: =IFERROR(IF(C11="", "", _xludf.IFS(12>=IFERROR(VLOOKUP(C11, 'Birim Fiyat Master'!A$6:M$30, 13, FALSE), 99), VLOOKUP(C11, 'Birim Fiyat Master'!A$6:M$30, 12, FALSE), 12>=IFERROR(VLOOKUP(C11, 'Birim Fiyat Master'!A$6:M$30, 11, FALSE), 99), VLOOKUP(C11, 'Birim Fiyat Master'!A$6:M$30, 10, FALSE), 12>=IFERROR(VLOOKUP(C11, 'Birim Fiyat Master'!A$6:M$30, 9, FALSE), 99), VLOOKUP(C11, 'Birim Fiyat Master'!A$6:M$30, 8, FALSE), 12>=IFERROR(VLOOKUP(C11, 'Birim Fiyat Master'!A$6:M$30, 7, FALSE), 99), VLOOKUP(C11, 'Birim Fiyat Master'!A$6:M$30, 6, FALSE), TRUE, VLOOKUP(C11, 'Birim Fiyat Master'!A$6:M$30, 4, FALSE))), VLOOKUP(C11, 'Birim Fiyat Master'!A$6:M$30, 4, FALSE)) | BD11: =BA11*BC11 | BF11: =BB11+BE11 | BG11: =IFERROR(IF(C11="", "", _xludf.IFS(13>=IFERROR(VLOOKUP(C11, 'Birim Fiyat Master'!A$6:M$30, 13, FALSE), 99), VLOOKUP(C11, 'Birim Fiyat Master'!A$6:M$30, 12, FALSE), 13>=IFERROR(VLOOKUP(C11, 'Birim Fiyat Master'!A$6:M$30, 11, FALSE), 99), VLOOKUP(C11, 'Birim Fiyat Master'!A$6:M$30, 10, FALSE), 13>=IFERROR(VLOOKUP(C11, 'Birim Fiyat Master'!A$6:M$30, 9, FALSE), 99), VLOOKUP(C11, 'Birim Fiyat Master'!A$6:M$30, 8, FALSE), 13>=IFERROR(VLOOKUP(C11, 'Birim Fiyat Master'!A$6:M$30, 7, FALSE), 99), VLOOKUP(C11, 'Birim Fiyat Master'!A$6:M$30, 6, FALSE), TRUE, VLOOKUP(C11, 'Birim Fiyat Master'!A$6:M$30, 4, FALSE))), VLOOKUP(C11, 'Birim Fiyat Master'!A$6:M$30, 4, FALSE)) | BH11: =BE11*BG11 | BJ11: =BF11+BI11 | BK11: =IFERROR(IF(C11="", "", _xludf.IFS(14>=IFERROR(VLOOKUP(C11, 'Birim Fiyat Master'!A$6:M$30, 13, FALSE), 99), VLOOKUP(C11, 'Birim Fiyat Master'!A$6:M$30, 12, FALSE), 14>=IFERROR(VLOOKUP(C11, 'Birim Fiyat Master'!A$6:M$30, 11, FALSE), 99), VLOOKUP(C11, 'Birim Fiyat Master'!A$6:M$30, 10, FALSE), 14>=IFERROR(VLOOKUP(C11, 'Birim Fiyat Master'!A$6:M$30, 9, FALSE), 99), VLOOKUP(C11, 'Birim Fiyat Master'!A$6:M$30, 8, FALSE), 14>=IFERROR(VLOOKUP(C11, 'Birim Fiyat Master'!A$6:M$30, 7, FALSE), 99), VLOOKUP(C11, 'Birim Fiyat Master'!A$6:M$30, 6, FALSE), TRUE, VLOOKUP(C11, 'Birim Fiyat Master'!A$6:M$30, 4, FALSE))), VLOOKUP(C11, 'Birim Fiyat Master'!A$6:M$30, 4, FALSE)) | BL11: =BI11*BK11 | BN11: =BJ11+BM11 | BO11: =IFERROR(IF(C11="", "", _xludf.IFS(15>=IFERROR(VLOOKUP(C11, 'Birim Fiyat Master'!A$6:M$30, 13, FALSE), 99), VLOOKUP(C11, 'Birim Fiyat Master'!A$6:M$30, 12, FALSE), 15>=IFERROR(VLOOKUP(C11, 'Birim Fiyat Master'!A$6:M$30, 11, FALSE), 99), VLOOKUP(C11, 'Birim Fiyat Master'!A$6:M$30, 10, FALSE), 15>=IFERROR(VLOOKUP(C11, 'Birim Fiyat Master'!A$6:M$30, 9, FALSE), 99), VLOOKUP(C11, 'Birim Fiyat Master'!A$6:M$30, 8, FALSE), 15>=IFERROR(VLOOKUP(C11, 'Birim Fiyat Master'!A$6:M$30, 7, FALSE), 99), VLOOKUP(C11, 'Birim Fiyat Master'!A$6:M$30, 6, FALSE), TRUE, VLOOKUP(C11, 'Birim Fiyat Master'!A$6:M$30, 4, FALSE))), VLOOKUP(C11, 'Birim Fiyat Master'!A$6:M$30, 4, FALSE)) | BP11: =BM11*BO11
